Workbook

Sheet panel_choc_taux_suisse_2014_202
A1: canton | B1: year | C1: CLUSTER 0 | D1: CLUSTER 1 | E1: CLUSTER 2 | F1: rent_avg | G1: Z_score_rent | H1: log_rent_avg | I1: pop_cant | J1: Solde_migratoire | K1: migration_rate | L1: migration_rate_zscore | M1: immo_price_index | N1: immoo_price_index_zscore | O1: mortgage_rate | P1: change_mrtgrate | Q1: logement_propr | R1: debt_per_household_*1000 | S1: homeownership_rate | T1: Z-score-debt | U1: Z-score-ownrrate | V1: avg_income | W1: avg_income_zscore | X1: log_avg_income | Y1: unemployment_rate | Z1: z-score_unemployment | AA1: log_unemployment | AB1: share_65plus | AC1: housing_constr_tot | AD1: housing_construction_pc | AE1: exposure_index | AF1: shock_exposure | AG1: log_schockexposure | AH1: shockexposure_zscore | AI1: delta_rent | AJ1: delta_migration | AK1: delta_unemployment | AL1: delta_income
A2: AG | B2: 2014 | C2: 1 | D2: 0 | E2: 0 | F2: 1294.83 | G2: =(F2-AVERAGE($F$2:$F$261))/STDEV($F$2:$F$261) -> 0.10583317 | H2: =LN(F2) -> 7.1661347 | I2: 645277 | J2: 1819 | K2: =(J2/I2)*100 -> 0.28189444 | L2: =(K2-AVERAGE($K$2:$K$261))/STDEV($K$2:$K$261) -> 0.91569056 | M2: 1.0281149 | N2: =(M2-AVERAGE($M$2:$M$261))/STDEV($M$2:$M$261) -> 0.060154245 | O2: 1.95 | P2: 0 | Q2: 114360 | R2: =[1]Feuil1!J36/panel_choc_taux_suisse_2014_202!Q2 -> 5550.9998 | S2: 28.5 | T2: =(R2-AVERAGE($R$2:$R$261))/STDEV($R$2:$R$261) -> -0.85084975 | U2: =(S2-AVERAGE($S$2:$S$261))/STDEV($S$2:$S$261) -> -1.233605 | V2: 80757.233 | W2: =(V2-AVERAGE($V$2:$V$261))/STDEV($V$2:$V$261) -> -0.4447083 | X2: =LN(V2) -> 11.299203 | Y2: 2.8 | Z2: =(Y2-AVERAGE($Y$2:$Y$261))/STDEV($Y$2:$Y$261) -> 0.22959394 | AA2: =LN(Y2) -> 1.0296194 | AB2: 104387 | AC2: 4937 | AD2: =AC2/I2 -> 0.0076509778 | AE2: =0.5*T2+0.5*U2 -> -1.0422274 | AF2: =AE2*P2 -> 0 | AG2: =LN(1+AF2) -> 0 | AH2: =(AF2-AVERAGE($AF$2:$AF$261))/STDEV($AF$2:$AF$261) -> 0.0055297297 | AI2: =AF2*Q2 -> 0 | AJ2: =AI2*R2 -> 0 | AK2: 0 | AL2: 0
A3: AG | B3: 2015 | C3: 1 | D3: 0 | E3: 0 | F3: 1258.33 | G3: =(F3-AVERAGE($F$2:$F$261))/STDEV($F$2:$F$261) -> -0.079186785 | H3: =LN(F3) -> 7.1375407 | I3: 653675 | J3: 1501 | K3: =(J3/I3)*100 -> 0.22962481 | L3: =(K3-AVERAGE($K$2:$K$261))/STDEV($K$2:$K$261) -> 0.75396915 | M3: 1.0174024 | N3: =(M3-AVERAGE($M$2:$M$261))/STDEV($M$2:$M$261) -> -0.38706257 | O3: 1.84 | P3: =O3-O2 -> -0.11 | Q3: 117510 | R3: =[1]Feuil1!J37/panel_choc_taux_suisse_2014_202!Q3 -> 5583.203 | S3: 29.1 | T3: =(R3-AVERAGE($R$2:$R$261))/STDEV($R$2:$R$261) -> -0.8503082 | U3: =(S3-AVERAGE($S$2:$S$261))/STDEV($S$2:$S$261) -> -1.1730275 | V3: 81080.262 | W3: =(V3-AVERAGE($V$2:$V$261))/STDEV($V$2:$V$261) -> -0.42638089 | X3: =LN(V3) -> 11.303195 | Y3: 3 | Z3: =(Y3-AVERAGE($Y$2:$Y$261))/STDEV($Y$2:$Y$261) -> 0.40187222 | AA3: =LN(Y3) -> 1.0986123 | AB3: 107352 | AC3: 4839 | AD3: =AC3/I3 -> 0.0074027613 | AE3: =0.5*T3+0.5*U3 -> -1.0116679 | AF3: =AE3*P3 -> 0.11128347 | AG3: =LN(1+AF3) -> 0.10551562 | AH3: =(AF3-AVERAGE($AF$2:$AF$261))/STDEV($AF$2:$AF$261) -> 1.1499281 | AI3: =LN(F3)-LN(F2) -> -0.028593967 | AJ3: =K3-K2 -> -0.052269629 | AK3: =Y3-Y2 -> 0.2 | AL3: =LN(V3)-LN(V2) -> 0.0039920213
A4: AG | B4: 2016 | C4: 1 | D4: 0 | E4: 0 | F4: 1277 | G4: =(F4-AVERAGE($F$2:$F$261))/STDEV($F$2:$F$261) -> 0.015452188 | H4: =LN(F4) -> 7.1522689 | I4: 663462 | J4: 2036 | K4: =(J4/I4)*100 -> 0.30687515 | L4: =(K4-AVERAGE($K$2:$K$261))/STDEV($K$2:$K$261) -> 0.99298047 | M4: 0.98347652 | N4: =(M4-AVERAGE($M$2:$M$261))/STDEV($M$2:$M$261) -> -1.8033694 | O4: 1.71 | P4: =O4-O3 -> -0.13 | Q4: 118803 | R4: =[1]Feuil1!J38/panel_choc_taux_suisse_2014_202!Q4 -> 5686.5828 | S4: 29.4 | T4: =(R4-AVERAGE($R$2:$R$261))/STDEV($R$2:$R$261) -> -0.84856972 | U4: =(S4-AVERAGE($S$2:$S$261))/STDEV($S$2:$S$261) -> -1.1427388 | V4: 81647.824 | W4: =(V4-AVERAGE($V$2:$V$261))/STDEV($V$2:$V$261) -> -0.39417964 | X4: =LN(V4) -> 11.31017 | Y4: 3.2 | Z4: =(Y4-AVERAGE($Y$2:$Y$261))/STDEV($Y$2:$Y$261) -> 0.5741505 | AA4: =LN(Y4) -> 1.1631508 | AB4: 110298 | AC4: 5011 | AD4: =AC4/I4 -> 0.0075528063 | AE4: =0.5*T4+0.5*U4 -> -0.99565428 | AF4: =AE4*P4 -> 0.12943506 | AG4: =LN(1+AF4) -> 0.12171756 | AH4: =(AF4-AVERAGE($AF$2:$AF$261))/STDEV($AF$2:$AF$261) -> 1.3365924 | AI4: =LN(F4)-LN(F3) -> 0.014728132 | AJ4: =K4-K3 -> 0.077250335 | AK4: =Y4-Y3 -> 0.2 | AL4: =LN(V4)-LN(V3) -> 0.0069756137
A5: AG | B5: 2017 | C5: 1 | D5: 0 | E5: 0 | F5: 1274.5 | G5: =(F5-AVERAGE($F$2:$F$261))/STDEV($F$2:$F$261) -> 0.0027795885 | H5: =LN(F5) -> 7.1503092 | I5: 670988 | J5: 2175 | K5: =(J5/I5)*100 -> 0.32414887 | L5: =(K5-AVERAGE($K$2:$K$261))/STDEV($K$2:$K$261) -> 1.0464251 | M5: 1.0635157 | N5: =(M5-AVERAGE($M$2:$M$261))/STDEV($M$2:$M$261) -> 1.538032 | O5: 1.56 | P5: =O5-O4 -> -0.15 | Q5: 119226 | R5: =[1]Feuil1!J39/panel_choc_taux_suisse_2014_202!Q5 -> 5807.2275 | S5: 29.2 | T5: =(R5-AVERAGE($R$2:$R$261))/STDEV($R$2:$R$261) -> -0.84654089 | U5: =(S5-AVERAGE($S$2:$S$261))/STDEV($S$2:$S$261) -> -1.1629313 | V5: 81974.415 | W5: =(V5-AVERAGE($V$2:$V$261))/STDEV($V$2:$V$261) -> -0.37565011 | X5: =LN(V5) -> 11.314162 | Y5: 3 | Z5: =(Y5-AVERAGE($Y$2:$Y$261))/STDEV($Y$2:$Y$261) -> 0.40187222 | AA5: =LN(Y5) -> 1.0986123 | AB5: 116424 | AC5: 5680 | AD5: =AC5/I5 -> 0.008465129 | AE5: =0.5*T5+0.5*U5 -> -1.0047361 | AF5: =AE5*P5 -> 0.15071042 | AG5: =LN(1+AF5) -> 0.1403795 | AH5: =(AF5-AVERAGE($AF$2:$AF$261))/STDEV($AF$2:$AF$261) -> 1.5553804 | AI5: =LN(F5)-LN(F4) -> -0.0019596322 | AJ5: =K5-K4 -> 0.017273718 | AK5: =Y5-Y4 -> -0.2 | AL5: =LN(V5)-LN(V4) -> 0.0039920212
A6: AG | B6: 2018 | C6: 1 | D6: 0 | E6: 0 | F6: 1305.83 | G6: =(F6-AVERAGE($F$2:$F$261))/STDEV($F$2:$F$261) -> 0.16159261 | H6: =LN(F6) -> 7.1745941 | I6: 678207 | J6: 1875 | K6: =(J6/I6)*100 -> 0.27646427 | L6: =(K6-AVERAGE($K$2:$K$261))/STDEV($K$2:$K$261) -> 0.89888968 | M6: 1.0301139 | N6: =(M6-AVERAGE($M$2:$M$261))/STDEV($M$2:$M$261) -> 0.14360417 | O6: 1.5 | P6: =O6-O5 -> -0.06 | Q6: 114635 | R6: =[1]Feuil1!J40/panel_choc_taux_suisse_2014_202!Q6 -> 6200.891 | S6: 27.5 | T6: =(R6-AVERAGE($R$2:$R$261))/STDEV($R$2:$R$261) -> -0.83992085 | U6: =(S6-AVERAGE($S$2:$S$261))/STDEV($S$2:$S$261) -> -1.3345674 | V6: 82384.287 | W6: =(V6-AVERAGE($V$2:$V$261))/STDEV($V$2:$V$261) -> -0.35239556 | X6: =LN(V6) -> 11.31915 | Y6: 2.6 | Z6: =(Y6-AVERAGE($Y$2:$Y$261))/STDEV($Y$2:$Y$261) -> 0.057315659 | AA6: =LN(Y6) -> 0.95551145 | AB6: 119708 | AC6: 5113 | AD6: =AC6/I6 -> 0.0075389962 | AE6: =0.5*T6+0.5*U6 -> -1.0872441 | AF6: =AE6*P6 -> 0.065234646 | AG6: =LN(1+AF6) -> 0.0631951 | AH6: =(AF6-AVERAGE($AF$2:$AF$261))/STDEV($AF$2:$AF$261) -> 0.67637891 | AI6: =LN(F6)-LN(F5) -> 0.024284909 | AJ6: =K6-K5 -> -0.047684602 | AK6: =Y6-Y5 -> -0.4 | AL6: =LN(V6)-LN(V5) -> 0.0049875416
A7: AG | B7: 2019 | C7: 1 | D7: 0 | E7: 0 | F7: 1318.33 | G7: =(F7-AVERAGE($F$2:$F$261))/STDEV($F$2:$F$261) -> 0.2249556 | H7: =LN(F7) -> 7.1841211 | I7: 685845 | J7: 2041 | K7: =(J7/I7)*100 -> 0.29758911 | L7: =(K7-AVERAGE($K$2:$K$261))/STDEV($K$2:$K$261) -> 0.9642496 | M7: 1.0368889 | N7: =(M7-AVERAGE($M$2:$M$261))/STDEV($M$2:$M$261) -> 0.42644191 | O7: 1.43 | P7: =O7-O6 -> -0.07 | Q7: 116235 | R7: =[1]Feuil1!J41/panel_choc_taux_suisse_2014_202!Q7 -> 6281.8149 | S7: 27.7 | T7: =(R7-AVERAGE($R$2:$R$261))/STDEV($R$2:$R$261) -> -0.83855999 | U7: =(S7-AVERAGE($S$2:$S$261))/STDEV($S$2:$S$261) -> -1.3143749 | V7: 83126 | W7: =(V7-AVERAGE($V$2:$V$261))/STDEV($V$2:$V$261) -> -0.31031364 | X7: =LN(V7) -> 11.328113 | Y7: 2.5 | Z7: =(Y7-AVERAGE($Y$2:$Y$261))/STDEV($Y$2:$Y$261) -> -0.028823482 | AA7: =LN(Y7) -> 0.91629073 | AB7: 123012 | AC7: 4775 | AD7: =AC7/I7 -> 0.0069622145 | AE7: =0.5*T7+0.5*U7 -> -1.0764674 | AF7: =AE7*P7 -> 0.075352721 | AG7: =LN(1+AF7) -> 0.07264872 | AH7: =(AF7-AVERAGE($AF$2:$AF$261))/STDEV($AF$2:$AF$261) -> 0.78042947 | AI7: =LN(F7)-LN(F6) -> 0.0095269302 | AJ7: =K7-K6 -> 0.02112484 | AK7: =Y7-Y6 -> -0.1 | AL7: =LN(V7)-LN(V6) -> 0.0089628028
A8: AG | B8: 2020 | C8: 1 | D8: 0 | E8: 0 | F8: 1335.17 | G8: =(F8-AVERAGE($F$2:$F$261))/STDEV($F$2:$F$261) -> 0.31031823 | H8: =LN(F8) -> 7.1968139 | I8: 694072 | J8: 2769 | K8: =(J8/I8)*100 -> 0.39894996 | L8: =(K8-AVERAGE($K$2:$K$261))/STDEV($K$2:$K$261) -> 1.2778585 | M8: 1.0413346 | N8: =(M8-AVERAGE($M$2:$M$261))/STDEV($M$2:$M$261) -> 0.61203885 | O8: 1.33 | P8: =O8-O7 -> -0.1 | Q8: 113779 | R8: =[1]Feuil1!J42/panel_choc_taux_suisse_2014_202!Q8 -> 6586.6001 | S8: 27.4 | T8: =(R8-AVERAGE($R$2:$R$261))/STDEV($R$2:$R$261) -> -0.83343457 | U8: =(S8-AVERAGE($S$2:$S$261))/STDEV($S$2:$S$261) -> -1.3446636 | V8: 83790.751 | W8: =(V8-AVERAGE($V$2:$V$261))/STDEV($V$2:$V$261) -> -0.27259822 | X8: =LN(V8) -> 11.336078 | Y8: 3.4 | Z8: =(Y8-AVERAGE($Y$2:$Y$261))/STDEV($Y$2:$Y$261) -> 0.74642878 | AA8: =LN(Y8) -> 1.2237754 | AB8: 126168 | AC8: 3771 | AD8: =AC8/I8 -> 0.0054331539 | AE8: =0.5*T8+0.5*U8 -> -1.0890491 | AF8: =AE8*P8 -> 0.10890491 | AG8: =LN(1+AF8) -> 0.10337296 | AH8: =(AF8-AVERAGE($AF$2:$AF$261))/STDEV($AF$2:$AF$261) -> 1.1254679 | AI8: =LN(F8)-LN(F7) -> 0.01269284 | AJ8: =K8-K7 -> 0.10136086 | AK8: =Y8-Y7 -> 0.9 | AL8: =LN(V8)-LN(V7) -> 0.0079651081
A9: AG | B9: 2021 | C9: 1 | D9: 0 | E9: 0 | F9: 1341.67 | G9: =(F9-AVERAGE($F$2:$F$261))/STDEV($F$2:$F$261) -> 0.34326699 | H9: =LN(F9) -> 7.2016704 | I9: 703086 | J9: 3429 | K9: =(J9/I9)*100 -> 0.48770705 | L9: =(K9-AVERAGE($K$2:$K$261))/STDEV($K$2:$K$261) -> 1.5524715 | M9: 1.0457436 | N9: =(M9-AVERAGE($M$2:$M$261))/STDEV($M$2:$M$261) -> 0.79609897 | O9: 1.25 | P9: =O9-O8 -> -0.08 | Q9: 116256 | R9: =[1]Feuil1!J43/panel_choc_taux_suisse_2014_202!Q9 -> 6650.4076 | S9: 27.6 | T9: =(R9-AVERAGE($R$2:$R$261))/STDEV($R$2:$R$261) -> -0.83236155 | U9: =(S9-AVERAGE($S$2:$S$261))/STDEV($S$2:$S$261) -> -1.3244711 | V9: 83623.17 | W9: =(V9-AVERAGE($V$2:$V$261))/STDEV($V$2:$V$261) -> -0.28210614 | X9: =LN(V9) -> 11.334076 | Y9: 3.4 | Z9: =(Y9-AVERAGE($Y$2:$Y$261))/STDEV($Y$2:$Y$261) -> 0.74642878 | AA9: =LN(Y9) -> 1.2237754 | AB9: 129531 | AC9: 3815 | AD9: =AC9/I9 -> 0.0054260787 | AE9: =0.5*T9+0.5*U9 -> -1.0784163 | AF9: =AE9*P9 -> 0.086273307 | AG9: =LN(1+AF9) -> 0.082752854 | AH9: =(AF9-AVERAGE($AF$2:$AF$261))/STDEV($AF$2:$AF$261) -> 0.89273278 | AI9: =LN(F9)-LN(F8) -> 0.0048564821 | AJ9: =K9-K8 -> 0.088757087 | AK9: =Y9-Y8 -> 0 | AL9: =LN(V9)-LN(V8) -> -0.0020020026
A10: AG | B10: 2022 | C10: 1 | D10: 0 | E10: 0 | F10: 1369.17 | G10: =(F10-AVERAGE($F$2:$F$261))/STDEV($F$2:$F$261) -> 0.48266559 | H10: =LN(F10) -> 7.22196 | I10: 711232 | J10: 2615 | K10: =(J10/I10)*100 -> 0.36767187 | L10: =(K10-AVERAGE($K$2:$K$261))/STDEV($K$2:$K$261) -> 1.1810846 | M10: 0.98600652 | N10: =(M10-AVERAGE($M$2:$M$261))/STDEV($M$2:$M$261) -> -1.6977493 | O10: 1.21 | P10: =O10-O9 -> -0.04 | Q10: 112419 | R10: =[1]Feuil1!J44/panel_choc_taux_suisse_2014_202!Q10 -> 7081.8322 | S10: 26.8 | T10: =(R10-AVERAGE($R$2:$R$261))/STDEV($R$2:$R$261) -> -0.8251065 | U10: =(S10-AVERAGE($S$2:$S$261))/STDEV($S$2:$S$261) -> -1.405241 | V10: 84375.779 | W10: =(V10-AVERAGE($V$2:$V$261))/STDEV($V$2:$V$261) -> -0.23940605 | X10: =LN(V10) -> 11.343036 | Y10: 2.5 | Z10: =(Y10-AVERAGE($Y$2:$Y$261))/STDEV($Y$2:$Y$261) -> -0.028823482 | AA10: =LN(Y10) -> 0.91629073 | AB10: 133099 | AC10: 3679 | AD10: =AC10/I10 -> 0.0051727144 | AE10: =0.5*T10+0.5*U10 -> -1.1151738 | AF10: =AE10*P10 -> 0.044606951 | AG10: =LN(1+AF10) -> 0.043640691 | AH10: =(AF10-AVERAGE($AF$2:$AF$261))/STDEV($AF$2:$AF$261) -> 0.46425125 | AI10: =LN(F10)-LN(F9) -> 0.02028961 | AJ10: =K10-K9 -> -0.12003518 | AK10: =Y10-Y9 -> -0.9 | AL10: =LN(V10)-LN(V9) -> 0.0089597414
A11: AG | B11: 2023 | C11: 1 | D11: 0 | E11: 0 | F11: 1523.14 | G11: =(F11-AVERAGE($F$2:$F$261))/STDEV($F$2:$F$261) -> 1.2631457 | H11: =LN(F11) -> 7.3285293 | I11: 726894 | J11: 3128 | K11: =(J11/I11)*100 -> 0.43032409 | L11: =(K11-AVERAGE($K$2:$K$261))/STDEV($K$2:$K$261) -> 1.3749295 | M11: 1.0341431 | N11: =(M11-AVERAGE($M$2:$M$261))/STDEV($M$2:$M$261) -> 0.31181116 | O11: 1.48 | P11: =O11-O10 -> 0.27 | Q11: 111712 | R11: =[1]Feuil1!J45/panel_choc_taux_suisse_2014_202!Q11 -> 7278.4333 | S11: 26.7 | T11: =(R11-AVERAGE($R$2:$R$261))/STDEV($R$2:$R$261) -> -0.82180036 | U11: =(S11-AVERAGE($S$2:$S$261))/STDEV($S$2:$S$261) -> -1.4153373 | V11: 98719.661 | W11: =(V11-AVERAGE($V$2:$V$261))/STDEV($V$2:$V$261) -> 0.57441021 | X11: =LN(V11) -> 11.500039 | Y11: 2.2 | Z11: =(Y11-AVERAGE($Y$2:$Y$261))/STDEV($Y$2:$Y$261) -> -0.2872409 | AA11: =LN(Y11) -> 0.78845736 | AB11: 137011 | AC11: 4193 | AD11: =AC11/I11 -> 0.0057683789 | AE11: =0.5*T11+0.5*U11 -> -1.1185688 | AF11: =AE11*P11 -> -0.30201358 | AG11: =LN(1+AF11) -> -0.35955563 | AH11: =(AF11-AVERAGE($AF$2:$AF$261))/STDEV($AF$2:$AF$261) -> -3.1002672 | AI11: =LN(F11)-LN(F10) -> 0.10656928 | AJ11: =K11-K10 -> 0.06265222 | AK11: =Y11-Y10 -> -0.3 | AL11: =LN(V11)-LN(V10) -> 0.15700375
A12: AI | B12: 2014 | C12: 1 | D12: 0 | E12: 0 | F12: 1299 | G12: =(F12-AVERAGE($F$2:$F$261))/STDEV($F$2:$F$261) -> 0.12697106 | H12: =LN(F12) -> 7.16935 | I12: 15854 | J12: 18 | K12: =(J12/I12)*100 -> 0.11353602 | L12: =(K12-AVERAGE($K$2:$K$261))/STDEV($K$2:$K$261) -> 0.39479225 | M12: 1.0281149 | N12: =(M12-AVERAGE($M$2:$M$261))/STDEV($M$2:$M$261) -> 0.060154245 | O12: 1.95 | P12: 0 | Q12: 131949 | R12: =[1]Feuil1!J46/panel_choc_taux_suisse_2014_202!Q12 -> 4811.0432 | S12: 39.8 | T12: =(R12-AVERAGE($R$2:$R$261))/STDEV($R$2:$R$261) -> -0.86329323 | U12: =(S12-AVERAGE($S$2:$S$261))/STDEV($S$2:$S$261) -> -0.092730065 | V12: 86397.741 | W12: =(V12-AVERAGE($V$2:$V$261))/STDEV($V$2:$V$261) -> -0.12468772 | X12: =LN(V12) -> 11.366717 | Y12: 1.1 | Z12: =(Y12-AVERAGE($Y$2:$Y$261))/STDEV($Y$2:$Y$261) -> -1.2347714 | AA12: =LN(Y12) -> 0.09531018 | AB12: 2813 | AC12: 53 | AD12: =AC12/I12 -> 0.0033430049 | AE12: =0.5*T12+0.5*U12 -> -0.47801165 | AF12: =AE12*P12 -> 0 | AG12: =LN(1+AF12) -> 0 | AH12: =(AF12-AVERAGE($AF$2:$AF$261))/STDEV($AF$2:$AF$261) -> 0.0055297297 | AI12: 0 | AJ12: 0 | AK12: 0 | AL12: 0
A13: AI | B13: 2015 | C13: 1 | D13: 0 | E13: 0 | F13: 1204 | G13: =(F13-AVERAGE($F$2:$F$261))/STDEV($F$2:$F$261) -> -0.35458772 | H13: =LN(F13) -> 7.0934046 | I13: 15974 | J13: 32 | K13: =(J13/I13)*100 -> 0.20032553 | L13: =(K13-AVERAGE($K$2:$K$261))/STDEV($K$2:$K$261) -> 0.66331763 | M13: 1.0174024 | N13: =(M13-AVERAGE($M$2:$M$261))/STDEV($M$2:$M$261) -> -0.38706257 | O13: 1.84 | P13: -0.11 | Q13: 134396 | R13: =[1]Feuil1!J47/panel_choc_taux_suisse_2014_202!Q13 -> 4881.7092 | S13: 40.9 | T13: =(R13-AVERAGE($R$2:$R$261))/STDEV($R$2:$R$261) -> -0.86210487 | U13: =(S13-AVERAGE($S$2:$S$261))/STDEV($S$2:$S$261) -> 0.018328555 | V13: 86743.332 | W13: =(V13-AVERAGE($V$2:$V$261))/STDEV($V$2:$V$261) -> -0.10508023 | X13: =LN(V13) -> 11.370709 | Y13: 1 | Z13: =(Y13-AVERAGE($Y$2:$Y$261))/STDEV($Y$2:$Y$261) -> -1.3209106 | AA13: =LN(Y13) -> 0 | AB13: 2865 | AC13: 146 | AD13: =AC13/I13 -> 0.0091398523 | AE13: =0.5*T13+0.5*U13 -> -0.42188816 | AF13: =AE13*P13 -> 0.046407697 | AG13: =LN(1+AF13) -> 0.045363058 | AH13: =(AF13-AVERAGE($AF$2:$AF$261))/STDEV($AF$2:$AF$261) -> 0.48276947 | AI13: =LN(F13)-LN(F12) -> -0.075945391 | AJ13: =K13-K12 -> 0.086789513 | AK13: =Y13-Y12 -> -0.1 | AL13: =LN(V13)-LN(V12) -> 0.0039920212
A14: AI | B14: 2016 | C14: 1 | D14: 0 | E14: 0 | F14: 1110.17 | G14: =(F14-AVERAGE($F$2:$F$261))/STDEV($F$2:$F$261) -> -0.83021573 | H14: =LN(F14) -> 7.0122684 | I14: 16003 | J14: -8 | K14: =(J14/I14)*100 -> -0.049990627 | L14: =(K14-AVERAGE($K$2:$K$261))/STDEV($K$2:$K$261) -> -0.11115659 | M14: 0.98347652 | N14: =(M14-AVERAGE($M$2:$M$261))/STDEV($M$2:$M$261) -> -1.8033694 | O14: 1.71 | P14: -0.13 | Q14: 137001 | R14: =[1]Feuil1!J48/panel_choc_taux_suisse_2014_202!Q14 -> 4931.2274 | S14: 40.3 | T14: =(R14-AVERAGE($R$2:$R$261))/STDEV($R$2:$R$261) -> -0.86127215 | U14: =(S14-AVERAGE($S$2:$S$261))/STDEV($S$2:$S$261) -> -0.042248874 | V14: 87350.536 | W14: =(V14-AVERAGE($V$2:$V$261))/STDEV($V$2:$V$261) -> -0.070629867 | X14: =LN(V14) -> 11.377684 | Y14: 1.1 | Z14: =(Y14-AVERAGE($Y$2:$Y$261))/STDEV($Y$2:$Y$261) -> -1.2347714 | AA14: =LN(Y14) -> 0.09531018 | AB14: 2924 | AC14: 49 | AD14: =AC14/I14 -> 0.0030619259 | AE14: =0.5*T14+0.5*U14 -> -0.45176051 | AF14: =AE14*P14 -> 0.058728866 | AG14: =LN(1+AF14) -> 0.057069006 | AH14: =(AF14-AVERAGE($AF$2:$AF$261))/STDEV($AF$2:$AF$261) -> 0.60947585 | AI14: =LN(F14)-LN(F13) -> -0.08113619 | AJ14: =K14-K13 -> -0.25031616 | AK14: =Y14-Y13 -> 0.1 | AL14: =LN(V14)-LN(V13) -> 0.0069756138
A15: AI | B15: 2017 | C15: 1 | D15: 0 | E15: 0 | F15: 1087.17 | G15: =(F15-AVERAGE($F$2:$F$261))/STDEV($F$2:$F$261) -> -0.94680364 | H15: =LN(F15) -> 6.9913333 | I15: 16105 | J15: -43 | K15: =(J15/I15)*100 -> -0.26699783 | L15: =(K15-AVERAGE($K$2:$K$261))/STDEV($K$2:$K$261) -> -0.78257344 | M15: 1.0635157 | N15: =(M15-AVERAGE($M$2:$M$261))/STDEV($M$2:$M$261) -> 1.538032 | O15: 1.56 | P15: -0.15 | Q15: 137023 | R15: =[1]Feuil1!J49/panel_choc_taux_suisse_2014_202!Q15 -> 5052.9656 | S15: 40.3 | T15: =(R15-AVERAGE($R$2:$R$261))/STDEV($R$2:$R$261) -> -0.85922494 | U15: =(S15-AVERAGE($S$2:$S$261))/STDEV($S$2:$S$261) -> -0.042248874 | V15: 87699.938 | W15: =(V15-AVERAGE($V$2:$V$261))/STDEV($V$2:$V$261) -> -0.050806144 | X15: =LN(V15) -> 11.381676 | Y15: 1 | Z15: =(Y15-AVERAGE($Y$2:$Y$261))/STDEV($Y$2:$Y$261) -> -1.3209106 | AA15: =LN(Y15) -> 0 | AB15: 3013 | AC15: 63 | AD15: =AC15/I15 -> 0.0039118286 | AE15: =0.5*T15+0.5*U15 -> -0.45073691 | AF15: =AE15*P15 -> 0.067610536 | AG15: =LN(1+AF15) -> 0.065423007 | AH15: =(AF15-AVERAGE($AF$2:$AF$261))/STDEV($AF$2:$AF$261) -> 0.70081168 | AI15: =LN(F15)-LN(F14) -> -0.020935167 | AJ15: =K15-K14 -> -0.2170072 | AK15: =Y15-Y14 -> -0.1 | AL15: =LN(V15)-LN(V14) -> 0.0039920212
A16: AI | B16: 2018 | C16: 1 | D16: 0 | E16: 0 | F16: 1134.17 | G16: =(F16-AVERAGE($F$2:$F$261))/STDEV($F$2:$F$261) -> -0.70855877 | H16: =LN(F16) -> 7.0336564 | I16: 16145 | J16: -53 | K16: =(J16/I16)*100 -> -0.32827501 | L16: =(K16-AVERAGE($K$2:$K$261))/STDEV($K$2:$K$261) -> -0.97216407 | M16: 1.0301139 | N16: =(M16-AVERAGE($M$2:$M$261))/STDEV($M$2:$M$261) -> 0.14360417 | O16: 1.5 | P16: -0.06 | Q16: 131491 | R16: =[1]Feuil1!J50/panel_choc_taux_suisse_2014_202!Q16 -> 5405.9908 | S16: 38.8 | T16: =(R16-AVERAGE($R$2:$R$261))/STDEV($R$2:$R$261) -> -0.85328829 | U16: =(S16-AVERAGE($S$2:$S$261))/STDEV($S$2:$S$261) -> -0.19369245 | V16: 88138.438 | W16: =(V16-AVERAGE($V$2:$V$261))/STDEV($V$2:$V$261) -> -0.025927372 | X16: =LN(V16) -> 11.386664 | Y16: 1 | Z16: =(Y16-AVERAGE($Y$2:$Y$261))/STDEV($Y$2:$Y$261) -> -1.3209106 | AA16: =LN(Y16) -> 0 | AB16: 3091 | AC16: 134 | AD16: =AC16/I16 -> 0.0082997832 | AE16: =0.5*T16+0.5*U16 -> -0.52349037 | AF16: =AE16*P16 -> 0.031409422 | AG16: =LN(1+AF16) -> 0.030926238 | AH16: =(AF16-AVERAGE($AF$2:$AF$261))/STDEV($AF$2:$AF$261) -> 0.32853271 | AI16: =LN(F16)-LN(F15) -> 0.042323116 | AJ16: =K16-K15 -> -0.061277181 | AK16: =Y16-Y15 -> 0 | AL16: =LN(V16)-LN(V15) -> 0.0049875415
A17: AI | B17: 2019 | C17: 1 | D17: 0 | E17: 0 | F17: 1345.2 | G17: =(F17-AVERAGE($F$2:$F$261))/STDEV($F$2:$F$261) -> 0.3611607 | H17: =LN(F17) -> 7.204298 | I17: 16128 | J17: -96 | K17: =(J17/I17)*100 -> -0.5952381 | L17: =(K17-AVERAGE($K$2:$K$261))/STDEV($K$2:$K$261) -> -1.7981436 | M17: 1.0368889 | N17: =(M17-AVERAGE($M$2:$M$261))/STDEV($M$2:$M$261) -> 0.42644191 | O17: 1.43 | P17: -0.07 | Q17: 131076 | R17: =[1]Feuil1!J51/panel_choc_taux_suisse_2014_202!Q17 -> 5570.5602 | S17: 38.8 | T17: =(R17-AVERAGE($R$2:$R$261))/STDEV($R$2:$R$261) -> -0.85052081 | U17: =(S17-AVERAGE($S$2:$S$261))/STDEV($S$2:$S$261) -> -0.19369245 | V17: 88932 | W17: =(V17-AVERAGE($V$2:$V$261))/STDEV($V$2:$V$261) -> 0.019096286 | X17: =LN(V17) -> 11.395627 | Y17: 1.1 | Z17: =(Y17-AVERAGE($Y$2:$Y$261))/STDEV($Y$2:$Y$261) -> -1.2347714 | AA17: =LN(Y17) -> 0.09531018 | AB17: 3157 | AC17: 45 | AD17: =AC17/I17 -> 0.0027901786 | AE17: =0.5*T17+0.5*U17 -> -0.52210663 | AF17: =AE17*P17 -> 0.036547464 | AG17: =LN(1+AF17) -> 0.035895444 | AH17: =(AF17-AVERAGE($AF$2:$AF$261))/STDEV($AF$2:$AF$261) -> 0.38137044 | AI17: =LN(F17)-LN(F16) -> 0.17064159 | AJ17: =K17-K16 -> -0.26696309 | AK17: =Y17-Y16 -> 0.1 | AL17: =LN(V17)-LN(V16) -> 0.008963301
A18: AI | B18: 2020 | C18: 1 | D18: 0 | E18: 0 | F18: 1354.4 | G18: =(F18-AVERAGE($F$2:$F$261))/STDEV($F$2:$F$261) -> 0.40779587 | H18: =LN(F18) -> 7.2111138 | I18: 16145 | J18: 75 | K18: =(J18/I18)*100 -> 0.46454011 | L18: =(K18-AVERAGE($K$2:$K$261))/STDEV($K$2:$K$261) -> 1.4807934 | M18: 1.0413346 | N18: =(M18-AVERAGE($M$2:$M$261))/STDEV($M$2:$M$261) -> 0.61203885 | O18: 1.33 | P18: -0.1 | Q18: 131551 | R18: =[1]Feuil1!J52/panel_choc_taux_suisse_2014_202!Q18 -> 5696.7774 | S18: 38.3 | T18: =(R18-AVERAGE($R$2:$R$261))/STDEV($R$2:$R$261) -> -0.84839828 | U18: =(S18-AVERAGE($S$2:$S$261))/STDEV($S$2:$S$261) -> -0.24417364 | V18: 89643.137 | W18: =(V18-AVERAGE($V$2:$V$261))/STDEV($V$2:$V$261) -> 0.059443437 | X18: =LN(V18) -> 11.403592 | Y18: 1.1 | Z18: =(Y18-AVERAGE($Y$2:$Y$261))/STDEV($Y$2:$Y$261) -> -1.2347714 | AA18: =LN(Y18) -> 0.09531018 | AB18: 3258 | AC18: 196 | AD18: =AC18/I18 -> 0.012139981 | AE18: =0.5*T18+0.5*U18 -> -0.54628596 | AF18: =AE18*P18 -> 0.054628596 | AG18: =LN(1+AF18) -> 0.053188663 | AH18: =(AF18-AVERAGE($AF$2:$AF$261))/STDEV($AF$2:$AF$261) -> 0.56731017 | AI18: =LN(F18)-LN(F17) -> 0.006815851 | AJ18: =K18-K17 -> 1.0597782 | AK18: =Y18-Y17 -> 0 | AL18: =LN(V18)-LN(V17) -> 0.0079646101
A19: AI | B19: 2021 | C19: 1 | D19: 0 | E19: 0 | F19: 1388.6 | G19: =(F19-AVERAGE($F$2:$F$261))/STDEV($F$2:$F$261) -> 0.58115703 | H19: =LN(F19) -> 7.2360513 | I19: 16128 | J19: -6 | K19: =(J19/I19)*100 -> -0.037202381 | L19: =(K19-AVERAGE($K$2:$K$261))/STDEV($K$2:$K$261) -> -0.071589964 | M19: 1.0457436 | N19: =(M19-AVERAGE($M$2:$M$261))/STDEV($M$2:$M$261) -> 0.79609897 | O19: 1.25 | P19: -0.08 | Q19: 132102 | R19: =[1]Feuil1!J53/panel_choc_taux_suisse_2014_202!Q19 -> 5852.6728 | S19: 38.4 | T19: =(R19-AVERAGE($R$2:$R$261))/STDEV($R$2:$R$261) -> -0.84577666 | U19: =(S19-AVERAGE($S$2:$S$261))/STDEV($S$2:$S$261) -> -0.2340774 | V19: 89463.851 | W19: =(V19-AVERAGE($V$2:$V$261))/STDEV($V$2:$V$261) -> 0.049271429 | X19: =LN(V19) -> 11.40159 | Y19: 0.8 | Z19: =(Y19-AVERAGE($Y$2:$Y$261))/STDEV($Y$2:$Y$261) -> -1.4931889 | AA19: =LN(Y19) -> -0.22314355 | AB19: 3327 | AC19: 45 | AD19: =AC19/I19 -> 0.0027901786 | AE19: =0.5*T19+0.5*U19 -> -0.53992703 | AF19: =AE19*P19 -> 0.043194162 | AG19: =LN(1+AF19) -> 0.042287316 | AH19: =(AF19-AVERAGE($AF$2:$AF$261))/STDEV($AF$2:$AF$261) -> 0.44972265 | AI19: =LN(F19)-LN(F18) -> 0.024937494 | AJ19: =K19-K18 -> -0.50174249 | AK19: =Y19-Y18 -> -0.3 | AL19: =LN(V19)-LN(V18) -> -0.0020020027
A20: AI | B20: 2022 | C20: 1 | D20: 0 | E20: 0 | F20: 1314.8 | G20: =(F20-AVERAGE($F$2:$F$261))/STDEV($F$2:$F$261) -> 0.20706189 | H20: =LN(F20) -> 7.1814398 | I20: 16360 | J20: 42 | K20: =(J20/I20)*100 -> 0.25672372 | L20: =(K20-AVERAGE($K$2:$K$261))/STDEV($K$2:$K$261) -> 0.83781273 | M20: 0.98600652 | N20: =(M20-AVERAGE($M$2:$M$261))/STDEV($M$2:$M$261) -> -1.6977493 | O20: 1.21 | P20: -0.04 | Q20: 131365 | R20: =[1]Feuil1!J54/panel_choc_taux_suisse_2014_202!Q20 -> 6060.4613 | S20: 38.1 | T20: =(R20-AVERAGE($R$2:$R$261))/STDEV($R$2:$R$261) -> -0.84228239 | U20: =(S20-AVERAGE($S$2:$S$261))/STDEV($S$2:$S$261) -> -0.26436611 | V20: 90269.025 | W20: =(V20-AVERAGE($V$2:$V$261))/STDEV($V$2:$V$261) -> 0.094953916 | X20: =LN(V20) -> 11.41055 | Y20: 0.5 | Z20: =(Y20-AVERAGE($Y$2:$Y$261))/STDEV($Y$2:$Y$261) -> -1.7516063 | AA20: =LN(Y20) -> -0.69314718 | AB20: 3350 | AC20: 73 | AD20: =AC20/I20 -> 0.0044621027 | AE20: =0.5*T20+0.5*U20 -> -0.55332425 | AF20: =AE20*P20 -> 0.02213297 | AG20: =LN(1+AF20) -> 0.021891591 | AH20: =(AF20-AVERAGE($AF$2:$AF$261))/STDEV($AF$2:$AF$261) -> 0.23313708 | AI20: =LN(F20)-LN(F19) -> -0.054611483 | AJ20: =K20-K19 -> 0.2939261 | AK20: =Y20-Y19 -> -0.3 | AL20: =LN(V20)-LN(V19) -> 0.0089597414
A21: AI | B21: 2023 | C21: 1 | D21: 0 | E21: 0 | F21: 1512.17 | G21: =(F21-AVERAGE($F$2:$F$261))/STDEV($F$2:$F$261) -> 1.2075383 | H21: =LN(F21) -> 7.321301 | I21: 16585 | J21: -28 | K21: =(J21/I21)*100 -> -0.16882725 | L21: =(K21-AVERAGE($K$2:$K$261))/STDEV($K$2:$K$261) -> -0.47883524 | M21: 1.0341431 | N21: =(M21-AVERAGE($M$2:$M$261))/STDEV($M$2:$M$261) -> 0.31181116 | O21: 1.48 | P21: 0.27 | Q21: 131788 | R21: =[1]Feuil1!J55/panel_choc_taux_suisse_2014_202!Q21 -> 6169.669 | S21: 38 | T21: =(R21-AVERAGE($R$2:$R$261))/STDEV($R$2:$R$261) -> -0.8404459 | U21: =(S21-AVERAGE($S$2:$S$261))/STDEV($S$2:$S$261) -> -0.27446235 | V21: 105614.76 | W21: =(V21-AVERAGE($V$2:$V$261))/STDEV($V$2:$V$261) -> 0.96561137 | X21: =LN(V21) -> 11.567553 | Y21: 0.5 | Z21: =(Y21-AVERAGE($Y$2:$Y$261))/STDEV($Y$2:$Y$261) -> -1.7516063 | AA21: =LN(Y21) -> -0.69314718 | AB21: 3445 | AC21: 93 | AD21: =AC21/I21 -> 0.0056074766 | AE21: =0.5*T21+0.5*U21 -> -0.55745412 | AF21: =AE21*P21 -> -0.15051261 | AG21: =LN(1+AF21) -> -0.16312219 | AH21: =(AF21-AVERAGE($AF$2:$AF$261))/STDEV($AF$2:$AF$261) -> -1.5422868 | AI21: =LN(F21)-LN(F20) -> 0.13986114 | AJ21: =K21-K20 -> -0.42555097 | AK21: =Y21-Y20 -> 0 | AL21: =LN(V21)-LN(V20) -> 0.15700375
A22: AR | B22: 2014 | C22: 1 | D22: 0 | E22: 0 | F22: 1116.17 | G22: =(F22-AVERAGE($F$2:$F$261))/STDEV($F$2:$F$261) -> -0.79980149 | H22: =LN(F22) -> 7.0176585 | I22: 54064 | J22: 103 | K22: =(J22/I22)*100 -> 0.19051495 | L22: =(K22-AVERAGE($K$2:$K$261))/STDEV($K$2:$K$261) -> 0.63296384 | M22: 1.0281149 | N22: =(M22-AVERAGE($M$2:$M$261))/STDEV($M$2:$M$261) -> 0.060154245 | O22: 1.95 | P22: 0 | Q22: 38293 | R22: =[1]Feuil1!J56/panel_choc_taux_suisse_2014_202!Q22 -> 16577.764 | S22: 34.8 | T22: =(R22-AVERAGE($R$2:$R$261))/STDEV($R$2:$R$261) -> -0.66541816 | U22: =(S22-AVERAGE($S$2:$S$261))/STDEV($S$2:$S$261) -> -0.59754197 | V22: 78168.884 | W22: =(V22-AVERAGE($V$2:$V$261))/STDEV($V$2:$V$261) -> -0.59156115 | X22: =LN(V22) -> 11.266627 | Y22: 1.7 | Z22: =(Y22-AVERAGE($Y$2:$Y$261))/STDEV($Y$2:$Y$261) -> -0.71793661 | AA22: =LN(Y22) -> 0.53062825 | AB22: 9842 | AC22: 307 | AD22: =AC22/I22 -> 0.0056784552 | AE22: =0.5*T22+0.5*U22 -> -0.63148007 | AF22: =AE22*P22 -> 0 | AG22: =LN(1+AF22) -> 0 | AH22: =(AF22-AVERAGE($AF$2:$AF$261))/STDEV($AF$2:$AF$261) -> 0.0055297297 | AI22: 0 | AJ22: 0 | AK22: 0 | AL22: 0
A23: AR | B23: 2015 | C23: 1 | D23: 0 | E23: 0 | F23: 1058.5 | G23: =(F23-AVERAGE($F$2:$F$261))/STDEV($F$2:$F$261) -> -1.092133 | H23: =LN(F23) -> 6.9646081 | I23: 54543 | J23: 71 | K23: =(J23/I23)*100 -> 0.13017252 | L23: =(K23-AVERAGE($K$2:$K$261))/STDEV($K$2:$K$261) -> 0.44626535 | M23: 1.0174024 | N23: =(M23-AVERAGE($M$2:$M$261))/STDEV($M$2:$M$261) -> -0.38706257 | O23: 1.84 | P23: -0.11 | Q23: 40236 | R23: =[1]Feuil1!J57/panel_choc_taux_suisse_2014_202!Q23 -> 16305.85 | S23: 36.3 | T23: =(R23-AVERAGE($R$2:$R$261))/STDEV($R$2:$R$261) -> -0.6699908 | U23: =(S23-AVERAGE($S$2:$S$261))/STDEV($S$2:$S$261) -> -0.4460984 | V23: 78481.56 | W23: =(V23-AVERAGE($V$2:$V$261))/STDEV($V$2:$V$261) -> -0.57382115 | X23: =LN(V23) -> 11.270619 | Y23: 1.9 | Z23: =(Y23-AVERAGE($Y$2:$Y$261))/STDEV($Y$2:$Y$261) -> -0.54565832 | AA23: =LN(Y23) -> 0.64185389 | AB23: 10056 | AC23: 233 | AD23: =AC23/I23 -> 0.0042718589 | AE23: =0.5*T23+0.5*U23 -> -0.5580446 | AF23: =AE23*P23 -> 0.061384906 | AG23: =LN(1+AF23) -> 0.059574571 | AH23: =(AF23-AVERAGE($AF$2:$AF$261))/STDEV($AF$2:$AF$261) -> 0.63678959 | AI23: =LN(F23)-LN(F22) -> -0.053050371 | AJ23: =K23-K22 -> -0.060342421 | AK23: =Y23-Y22 -> 0.2 | AL23: =LN(V23)-LN(V22) -> 0.0039920213
A24: AR | B24: 2016 | C24: 1 | D24: 0 | E24: 0 | F24: 1079.5 | G24: =(F24-AVERAGE($F$2:$F$261))/STDEV($F$2:$F$261) -> -0.98568318 | H24: =LN(F24) -> 6.9842532 | I24: 54954 | J24: -46 | K24: =(J24/I24)*100 -> -0.083706373 | L24: =(K24-AVERAGE($K$2:$K$261))/STDEV($K$2:$K$261) -> -0.21547258 | M24: 0.98347652 | N24: =(M24-AVERAGE($M$2:$M$261))/STDEV($M$2:$M$261) -> -1.8033694 | O24: 1.71 | P24: -0.13 | Q24: 40908 | R24: =[1]Feuil1!J58/panel_choc_taux_suisse_2014_202!Q24 -> 16514.694 | S24: 36.3 | T24: =(R24-AVERAGE($R$2:$R$261))/STDEV($R$2:$R$261) -> -0.66647879 | U24: =(S24-AVERAGE($S$2:$S$261))/STDEV($S$2:$S$261) -> -0.4460984 | V24: 79030.931 | W24: =(V24-AVERAGE($V$2:$V$261))/STDEV($V$2:$V$261) -> -0.54265198 | X24: =LN(V24) -> 11.277595 | Y24: 1.8 | Z24: =(Y24-AVERAGE($Y$2:$Y$261))/STDEV($Y$2:$Y$261) -> -0.63179746 | AA24: =LN(Y24) -> 0.58778666 | AB24: 10244 | AC24: 352 | AD24: =AC24/I24 -> 0.0064053572 | AE24: =0.5*T24+0.5*U24 -> -0.55628859 | AF24: =AE24*P24 -> 0.072317517 | AG24: =LN(1+AF24) -> 0.06982221 | AH24: =(AF24-AVERAGE($AF$2:$AF$261))/STDEV($AF$2:$AF$261) -> 0.74921655 | AI24: =LN(F24)-LN(F23) -> 0.019645159 | AJ24: =K24-K23 -> -0.2138789 | AK24: =Y24-Y23 -> -0.1 | AL24: =LN(V24)-LN(V23) -> 0.0069756137
A25: AR | B25: 2017 | C25: 1 | D25: 0 | E25: 0 | F25: 1086.33 | G25: =(F25-AVERAGE($F$2:$F$261))/STDEV($F$2:$F$261) -> -0.95106164 | H25: =LN(F25) -> 6.9905603 | I25: 55178 | J25: 51 | K25: =(J25/I25)*100 -> 0.092428142 | L25: =(K25-AVERAGE($K$2:$K$261))/STDEV($K$2:$K$261) -> 0.32948482 | M25: 1.0635157 | N25: =(M25-AVERAGE($M$2:$M$261))/STDEV($M$2:$M$261) -> 1.538032 | O25: 1.56 | P25: -0.15 | Q25: 39919 | R25: =[1]Feuil1!J59/panel_choc_taux_suisse_2014_202!Q25 -> 17344.435 | S25: 35.3 | T25: =(R25-AVERAGE($R$2:$R$261))/STDEV($R$2:$R$261) -> -0.65252544 | U25: =(S25-AVERAGE($S$2:$S$261))/STDEV($S$2:$S$261) -> -0.54706078 | V25: 79347.055 | W25: =(V25-AVERAGE($V$2:$V$261))/STDEV($V$2:$V$261) -> -0.52471634 | X25: =LN(V25) -> 11.281587 | Y25: 1.8 | Z25: =(Y25-AVERAGE($Y$2:$Y$261))/STDEV($Y$2:$Y$261) -> -0.63179746 | AA25: =LN(Y25) -> 0.58778666 | AB25: 10590 | AC25: 215 | AD25: =AC25/I25 -> 0.0038964805 | AE25: =0.5*T25+0.5*U25 -> -0.59979311 | AF25: =AE25*P25 -> 0.089968967 | AG25: =LN(1+AF25) -> 0.086149225 | AH25: =(AF25-AVERAGE($AF$2:$AF$261))/STDEV($AF$2:$AF$261) -> 0.93073758 | AI25: =LN(F25)-LN(F24) -> 0.0063070718 | AJ25: =K25-K24 -> 0.17613451 | AK25: =Y25-Y24 -> 0 | AL25: =LN(V25)-LN(V24) -> 0.0039920214
A26: AR | B26: 2018 | C26: 1 | D26: 0 | E26: 0 | F26: 1096.33 | G26: =(F26-AVERAGE($F$2:$F$261))/STDEV($F$2:$F$261) -> -0.90037124 | H26: =LN(F26) -> 6.9997235 | I26: 55234 | J26: -199 | K26: =(J26/I26)*100 -> -0.36028533 | L26: =(K26-AVERAGE($K$2:$K$261))/STDEV($K$2:$K$261) -> -1.0712035 | M26: 1.0301139 | N26: =(M26-AVERAGE($M$2:$M$261))/STDEV($M$2:$M$261) -> 0.14360417 | O26: 1.5 | P26: -0.06 | Q26: 39601 | R26: =[1]Feuil1!J60/panel_choc_taux_suisse_2014_202!Q26 -> 17950.03 | S26: 35 | T26: =(R26-AVERAGE($R$2:$R$261))/STDEV($R$2:$R$261) -> -0.64234145 | U26: =(S26-AVERAGE($S$2:$S$261))/STDEV($S$2:$S$261) -> -0.5773495 | V26: 79743.79 | W26: =(V26-AVERAGE($V$2:$V$261))/STDEV($V$2:$V$261) -> -0.50220712 | X26: =LN(V26) -> 11.286574 | Y26: 1.5 | Z26: =(Y26-AVERAGE($Y$2:$Y$261))/STDEV($Y$2:$Y$261) -> -0.89021489 | AA26: =LN(Y26) -> 0.40546511 | AB26: 10886 | AC26: 248 | AD26: =AC26/I26 -> 0.0044899881 | AE26: =0.5*T26+0.5*U26 -> -0.60984548 | AF26: =AE26*P26 -> 0.036590729 | AG26: =LN(1+AF26) -> 0.035937183 | AH26: =(AF26-AVERAGE($AF$2:$AF$261))/STDEV($AF$2:$AF$261) -> 0.38181536 | AI26: =LN(F26)-LN(F25) -> 0.0091631953 | AJ26: =K26-K25 -> -0.45271347 | AK26: =Y26-Y25 -> -0.3 | AL26: =LN(V26)-LN(V25) -> 0.0049875415
A27: AR | B27: 2019 | C27: 1 | D27: 0 | E27: 0 | F27: 1111.83 | G27: =(F27-AVERAGE($F$2:$F$261))/STDEV($F$2:$F$261) -> -0.82180112 | H27: =LN(F27) -> 7.0137626 | I27: 55445 | J27: 32 | K27: =(J27/I27)*100 -> 0.057714853 | L27: =(K27-AVERAGE($K$2:$K$261))/STDEV($K$2:$K$261) -> 0.22208246 | M27: 1.0368889 | N27: =(M27-AVERAGE($M$2:$M$261))/STDEV($M$2:$M$261) -> 0.42644191 | O27: 1.43 | P27: -0.07 | Q27: 40060 | R27: =[1]Feuil1!J61/panel_choc_taux_suisse_2014_202!Q27 -> 18226.829 | S27: 34.4 | T27: =(R27-AVERAGE($R$2:$R$261))/STDEV($R$2:$R$261) -> -0.63768667 | U27: =(S27-AVERAGE($S$2:$S$261))/STDEV($S$2:$S$261) -> -0.63792693 | V27: 80461 | W27: =(V27-AVERAGE($V$2:$V$261))/STDEV($V$2:$V$261) -> -0.4615154 | X27: =LN(V27) -> 11.295528 | Y27: 1.6 | Z27: =(Y27-AVERAGE($Y$2:$Y$261))/STDEV($Y$2:$Y$261) -> -0.80407575 | AA27: =LN(Y27) -> 0.47000363 | AB27: 11052 | AC27: 163 | AD27: =AC27/I27 -> 0.0029398503 | AE27: =0.5*T27+0.5*U27 -> -0.6378068 | AF27: =AE27*P27 -> 0.044646476 | AG27: =LN(1+AF27) -> 0.043678528 | AH27: =(AF27-AVERAGE($AF$2:$AF$261))/STDEV($AF$2:$AF$261) -> 0.46465771 | AI27: =LN(F27)-LN(F26) -> 0.014039068 | AJ27: =K27-K26 -> 0.41800018 | AK27: =Y27-Y26 -> 0.1 | AL27: =LN(V27)-LN(V26) -> 0.0089537262
A28: AR | B28: 2020 | C28: 1 | D28: 0 | E28: 0 | F28: 1106 | G28: =(F28-AVERAGE($F$2:$F$261))/STDEV($F$2:$F$261) -> -0.85135362 | H28: =LN(F28) -> 7.0085052 | I28: 55309 | J28: -306 | K28: =(J28/I28)*100 -> -0.55325535 | L28: =(K28-AVERAGE($K$2:$K$261))/STDEV($K$2:$K$261) -> -1.6682497 | M28: 1.0413346 | N28: =(M28-AVERAGE($M$2:$M$261))/STDEV($M$2:$M$261) -> 0.61203885 | O28: 1.33 | P28: -0.1 | Q28: 38323 | R28: =[1]Feuil1!J62/panel_choc_taux_suisse_2014_202!Q28 -> 19555.274 | S28: 34 | T28: =(R28-AVERAGE($R$2:$R$261))/STDEV($R$2:$R$261) -> -0.61534687 | U28: =(S28-AVERAGE($S$2:$S$261))/STDEV($S$2:$S$261) -> -0.67831188 | V28: 81105.176 | W28: =(V28-AVERAGE($V$2:$V$261))/STDEV($V$2:$V$261) -> -0.42496736 | X28: =LN(V28) -> 11.303502 | Y28: 2.2 | Z28: =(Y28-AVERAGE($Y$2:$Y$261))/STDEV($Y$2:$Y$261) -> -0.2872409 | AA28: =LN(Y28) -> 0.78845736 | AB28: 11206 | AC28: 215 | AD28: =AC28/I28 -> 0.0038872516 | AE28: =0.5*T28+0.5*U28 -> -0.64682937 | AF28: =AE28*P28 -> 0.064682937 | AG28: =LN(1+AF28) -> 0.062677043 | AH28: =(AF28-AVERAGE($AF$2:$AF$261))/STDEV($AF$2:$AF$261) -> 0.67070533 | AI28: =LN(F28)-LN(F27) -> -0.0052574033 | AJ28: =K28-K27 -> -0.6109702 | AK28: =Y28-Y27 -> 0.6 | AL28: =LN(V28)-LN(V27) -> 0.0079741848
A29: AR | B29: 2021 | C29: 1 | D29: 0 | E29: 0 | F29: 1147.83 | G29: =(F29-AVERAGE($F$2:$F$261))/STDEV($F$2:$F$261) -> -0.63931569 | H29: =LN(F29) -> 7.0456285 | I29: 55585 | J29: 157 | K29: =(J29/I29)*100 -> 0.2824503 | L29: =(K29-AVERAGE($K$2:$K$261))/STDEV($K$2:$K$261) -> 0.91741038 | M29: 1.0457436 | N29: =(M29-AVERAGE($M$2:$M$261))/STDEV($M$2:$M$261) -> 0.79609897 | O29: 1.25 | P29: -0.08 | Q29: 39391 | R29: =[1]Feuil1!J63/panel_choc_taux_suisse_2014_202!Q29 -> 19627.574 | S29: 34 | T29: =(R29-AVERAGE($R$2:$R$261))/STDEV($R$2:$R$261) -> -0.61413103 | U29: =(S29-AVERAGE($S$2:$S$261))/STDEV($S$2:$S$261) -> -0.67831188 | V29: 80942.966 | W29: =(V29-AVERAGE($V$2:$V$261))/STDEV($V$2:$V$261) -> -0.43417055 | X29: =LN(V29) -> 11.3015 | Y29: 1.9 | Z29: =(Y29-AVERAGE($Y$2:$Y$261))/STDEV($Y$2:$Y$261) -> -0.54565832 | AA29: =LN(Y29) -> 0.64185389 | AB29: 11410 | AC29: 241 | AD29: =AC29/I29 -> 0.0043357021 | AE29: =0.5*T29+0.5*U29 -> -0.64622145 | AF29: =AE29*P29 -> 0.051697716 | AG29: =LN(1+AF29) -> 0.050405731 | AH29: =(AF29-AVERAGE($AF$2:$AF$261))/STDEV($AF$2:$AF$261) -> 0.53717008 | AI29: =LN(F29)-LN(F28) -> 0.0371233 | AJ29: =K29-K28 -> 0.83570565 | AK29: =Y29-Y28 -> -0.3 | AL29: =LN(V29)-LN(V28) -> -0.0020020026
A30: AR | B30: 2022 | C30: 1 | D30: 0 | E30: 0 | F30: 1157.83 | G30: =(F30-AVERAGE($F$2:$F$261))/STDEV($F$2:$F$261) -> -0.58862529 | H30: =LN(F30) -> 7.0543028 | I30: 55759 | J30: -91 | K30: =(J30/I30)*100 -> -0.16320235 | L30: =(K30-AVERAGE($K$2:$K$261))/STDEV($K$2:$K$261) -> -0.46143188 | M30: 0.98600652 | N30: =(M30-AVERAGE($M$2:$M$261))/STDEV($M$2:$M$261) -> -1.6977493 | O30: 1.21 | P30: -0.04 | Q30: 38325 | R30: =[1]Feuil1!J64/panel_choc_taux_suisse_2014_202!Q30 -> 20773.19 | S30: 33.4 | T30: =(R30-AVERAGE($R$2:$R$261))/STDEV($R$2:$R$261) -> -0.59486579 | U30: =(S30-AVERAGE($S$2:$S$261))/STDEV($S$2:$S$261) -> -0.73888931 | V30: 81671.452 | W30: =(V30-AVERAGE($V$2:$V$261))/STDEV($V$2:$V$261) -> -0.39283904 | X30: =LN(V30) -> 11.31046 | Y30: 1.3 | Z30: =(Y30-AVERAGE($Y$2:$Y$261))/STDEV($Y$2:$Y$261) -> -1.0624932 | AA30: =LN(Y30) -> 0.26236426 | AB30: 11647 | AC30: 198 | AD30: =AC30/I30 -> 0.0035509963 | AE30: =0.5*T30+0.5*U30 -> -0.66687755 | AF30: =AE30*P30 -> 0.026675102 | AG30: =LN(1+AF30) -> 0.026325524 | AH30: =(AF30-AVERAGE($AF$2:$AF$261))/STDEV($AF$2:$AF$261) -> 0.27984669 | AI30: =LN(F30)-LN(F29) -> 0.0086743602 | AJ30: =K30-K29 -> -0.44565265 | AK30: =Y30-Y29 -> -0.6 | AL30: =LN(V30)-LN(V29) -> 0.0089597414
A31: AR | B31: 2023 | C31: 1 | D31: 0 | E31: 0 | F31: 1285.29 | G31: =(F31-AVERAGE($F$2:$F$261))/STDEV($F$2:$F$261) -> 0.057474528 | H31: =LN(F31) -> 7.1587397 | I31: 56495 | J31: 58 | K31: =(J31/I31)*100 -> 0.10266395 | L31: =(K31-AVERAGE($K$2:$K$261))/STDEV($K$2:$K$261) -> 0.36115426 | M31: 1.0341431 | N31: =(M31-AVERAGE($M$2:$M$261))/STDEV($M$2:$M$261) -> 0.31181116 | O31: 1.48 | P31: 0.27 | Q31: 39609 | R31: =[1]Feuil1!J65/panel_choc_taux_suisse_2014_202!Q31 -> 20527.868 | S31: 34.1 | T31: =(R31-AVERAGE($R$2:$R$261))/STDEV($R$2:$R$261) -> -0.59899123 | U31: =(S31-AVERAGE($S$2:$S$261))/STDEV($S$2:$S$261) -> -0.66821564 | V31: 95555.599 | W31: =(V31-AVERAGE($V$2:$V$261))/STDEV($V$2:$V$261) -> 0.39489361 | X31: =LN(V31) -> 11.467464 | Y31: 1.2 | Z31: =(Y31-AVERAGE($Y$2:$Y$261))/STDEV($Y$2:$Y$261) -> -1.1486323 | AA31: =LN(Y31) -> 0.18232156 | AB31: 11966 | AC31: 215 | AD31: =AC31/I31 -> 0.0038056465 | AE31: =0.5*T31+0.5*U31 -> -0.63360344 | AF31: =AE31*P31 -> -0.17107293 | AG31: =LN(1+AF31) -> -0.1876231 | AH31: =(AF31-AVERAGE($AF$2:$AF$261))/STDEV($AF$2:$AF$261) -> -1.7537215 | AI31: =LN(F31)-LN(F30) -> 0.10443681 | AJ31: =K31-K30 -> 0.26586631 | AK31: =Y31-Y30 -> -0.1 | AL31: =LN(V31)-LN(V30) -> 0.15700375
A32: BE | B32: 2014 | C32: 0 | D32: 0 | E32: 1 | F32: 1176 | G32: =(F32-AVERAGE($F$2:$F$261))/STDEV($F$2:$F$261) -> -0.49652083 | H32: =LN(F32) -> 7.0698741 | I32: 1009370 | J32: 712 | K32: =(J32/I32)*100 -> 0.070539049 | L32: =(K32-AVERAGE($K$2:$K$261))/STDEV($K$2:$K$261) -> 0.26176032 | M32: 1.0281149 | N32: =(M32-AVERAGE($M$2:$M$261))/STDEV($M$2:$M$261) -> 0.060154245 | O32: 1.95 | P32: 0 | Q32: 5311 | R32: =[1]Feuil1!J66/panel_choc_taux_suisse_2014_202!Q32 -> 119527.84 | S32: 47 | T32: =(R32-AVERAGE($R$2:$R$261))/STDEV($R$2:$R$261) -> 1.0658417 | U32: =(S32-AVERAGE($S$2:$S$261))/STDEV($S$2:$S$261) -> 0.63419908 | V32: 74053.074 | W32: =(V32-AVERAGE($V$2:$V$261))/STDEV($V$2:$V$261) -> -0.82507629 | X32: =LN(V32) -> 11.212537 | Y32: 2.3 | Z32: =(Y32-AVERAGE($Y$2:$Y$261))/STDEV($Y$2:$Y$261) -> -0.20110176 | AA32: =LN(Y32) -> 0.83290912 | AB32: 197134 | AC32: 4240 | AD32: =AC32/I32 -> 0.00420064 | AE32: =0.5*T32+0.5*U32 -> 0.8500204 | AF32: =AE32*P32 -> 0 | AG32: =LN(1+AF32) -> 0 | AH32: =(AF32-AVERAGE($AF$2:$AF$261))/STDEV($AF$2:$AF$261) -> 0.0055297297 | AI32: 0 | AJ32: 0 | AK32: 0 | AL32: 0
A33: BE | B33: 2015 | C33: 0 | D33: 0 | E33: 1 | F33: 1131.83 | G33: =(F33-AVERAGE($F$2:$F$261))/STDEV($F$2:$F$261) -> -0.72042032 | H33: =LN(F33) -> 7.0315911 | I33: 1017434 | J33: 856 | K33: =(J33/I33)*100 -> 0.084133221 | L33: =(K33-AVERAGE($K$2:$K$261))/STDEV($K$2:$K$261) -> 0.30382047 | M33: 1.0174024 | N33: =(M33-AVERAGE($M$2:$M$261))/STDEV($M$2:$M$261) -> -0.38706257 | O33: 1.84 | P33: -0.11 | Q33: 5595 | R33: =[1]Feuil1!J67/panel_choc_taux_suisse_2014_202!Q33 -> 117262.23 | S33: 49.7 | T33: =(R33-AVERAGE($R$2:$R$261))/STDEV($R$2:$R$261) -> 1.0277422 | U33: =(S33-AVERAGE($S$2:$S$261))/STDEV($S$2:$S$261) -> 0.90679752 | V33: 74349.286 | W33: =(V33-AVERAGE($V$2:$V$261))/STDEV($V$2:$V$261) -> -0.80827035 | X33: =LN(V33) -> 11.216529 | Y33: 2.5 | Z33: =(Y33-AVERAGE($Y$2:$Y$261))/STDEV($Y$2:$Y$261) -> -0.028823482 | AA33: =LN(Y33) -> 0.91629073 | AB33: 201208 | AC33: 4812 | AD33: =AC33/I33 -> 0.0047295451 | AE33: =0.5*T33+0.5*U33 -> 0.96726985 | AF33: =AE33*P33 -> -0.10639968 | AG33: =LN(1+AF33) -> -0.11249668 | AH33: =(AF33-AVERAGE($AF$2:$AF$261))/STDEV($AF$2:$AF$261) -> -1.0886456 | AI33: =LN(F33)-LN(F32) -> -0.038283058 | AJ33: =K33-K32 -> 0.013594172 | AK33: =Y33-Y32 -> 0.2 | AL33: =LN(V33)-LN(V32) -> 0.0039920213
A34: BE | B34: 2016 | C34: 0 | D34: 0 | E34: 1 | F34: 1151.17 | G34: =(F34-AVERAGE($F$2:$F$261))/STDEV($F$2:$F$261) -> -0.62238509 | H34: =LN(F34) -> 7.0485341 | I34: 1026464 | J34: 748 | K34: =(J34/I34)*100 -> 0.072871528 | L34: =(K34-AVERAGE($K$2:$K$261))/STDEV($K$2:$K$261) -> 0.26897697 | M34: 0.98347652 | N34: =(M34-AVERAGE($M$2:$M$261))/STDEV($M$2:$M$261) -> -1.8033694 | O34: 1.71 | P34: -0.13 | Q34: 5583 | R34: =[1]Feuil1!J68/panel_choc_taux_suisse_2014_202!Q34 -> 121007.18 | S34: 50.6 | T34: =(R34-AVERAGE($R$2:$R$261))/STDEV($R$2:$R$261) -> 1.0907191 | U34: =(S34-AVERAGE($S$2:$S$261))/STDEV($S$2:$S$261) -> 0.99766366 | V34: 74869.731 | W34: =(V34-AVERAGE($V$2:$V$261))/STDEV($V$2:$V$261) -> -0.77874232 | X34: =LN(V34) -> 11.223505 | Y34: 2.7 | Z34: =(Y34-AVERAGE($Y$2:$Y$261))/STDEV($Y$2:$Y$261) -> 0.1434548 | AA34: =LN(Y34) -> 0.99325177 | AB34: 204977 | AC34: 4283 | AD34: =AC34/I34 -> 0.0041725769 | AE34: =0.5*T34+0.5*U34 -> 1.0441914 | AF34: =AE34*P34 -> -0.13574488 | AG34: =LN(1+AF34) -> -0.14588728 | AH34: =(AF34-AVERAGE($AF$2:$AF$261))/STDEV($AF$2:$AF$261) -> -1.3904208 | AI34: =LN(F34)-LN(F33) -> 0.016943025 | AJ34: =K34-K33 -> -0.011261694 | AK34: =Y34-Y33 -> 0.2 | AL34: =LN(V34)-LN(V33) -> 0.0069756137
A35: BE | B35: 2017 | C35: 0 | D35: 0 | E35: 1 | F35: 1153.83 | G35: =(F35-AVERAGE($F$2:$F$261))/STDEV($F$2:$F$261) -> -0.60890145 | H35: =LN(F35) -> 7.0508421 | I35: 1031080 | J35: 364 | K35: =(J35/I35)*100 -> 0.035302789 | L35: =(K35-AVERAGE($K$2:$K$261))/STDEV($K$2:$K$261) -> 0.15273989 | M35: 1.0635157 | N35: =(M35-AVERAGE($M$2:$M$261))/STDEV($M$2:$M$261) -> 1.538032 | O35: 1.56 | P35: -0.15 | Q35: 5814 | R35: =[1]Feuil1!J69/panel_choc_taux_suisse_2014_202!Q35 -> 119087.12 | S35: 49.1 | T35: =(R35-AVERAGE($R$2:$R$261))/STDEV($R$2:$R$261) -> 1.0584304 | U35: =(S35-AVERAGE($S$2:$S$261))/STDEV($S$2:$S$261) -> 0.84622009 | V35: 75169.21 | W35: =(V35-AVERAGE($V$2:$V$261))/STDEV($V$2:$V$261) -> -0.76175104 | X35: =LN(V35) -> 11.227497 | Y35: 2.5 | Z35: =(Y35-AVERAGE($Y$2:$Y$261))/STDEV($Y$2:$Y$261) -> -0.028823482 | AA35: =LN(Y35) -> 0.91629073 | AB35: 211983 | AC35: 4282 | AD35: =AC35/I35 -> 0.004152927 | AE35: =0.5*T35+0.5*U35 -> 0.95232525 | AF35: =AE35*P35 -> -0.14284879 | AG35: =LN(1+AF35) -> -0.15414093 | AH35: =(AF35-AVERAGE($AF$2:$AF$261))/STDEV($AF$2:$AF$261) -> -1.4634748 | AI35: =LN(F35)-LN(F34) -> 0.0023080271 | AJ35: =K35-K34 -> -0.037568739 | AK35: =Y35-Y34 -> -0.2 | AL35: =LN(V35)-LN(V34) -> 0.0039920213
A36: BE | B36: 2018 | C36: 0 | D36: 0 | E36: 1 | F36: 1181 | G36: =(F36-AVERAGE($F$2:$F$261))/STDEV($F$2:$F$261) -> -0.47117564 | H36: =LN(F36) -> 7.0741168 | I36: 1034931 | J36: 57 | K36: =(J36/I36)*100 -> 0.0055076136 | L36: =(K36-AVERAGE($K$2:$K$261))/STDEV($K$2:$K$261) -> 0.060554083 | M36: 1.0301139 | N36: =(M36-AVERAGE($M$2:$M$261))/STDEV($M$2:$M$261) -> 0.14360417 | O36: 1.5 | P36: -0.06 | Q36: 5523 | R36: =[1]Feuil1!J70/panel_choc_taux_suisse_2014_202!Q36 -> 128705.26 | S36: 46.2 | T36: =(R36-AVERAGE($R$2:$R$261))/STDEV($R$2:$R$261) -> 1.2201738 | U36: =(S36-AVERAGE($S$2:$S$261))/STDEV($S$2:$S$261) -> 0.55342918 | V36: 75545.056 | W36: =(V36-AVERAGE($V$2:$V$261))/STDEV($V$2:$V$261) -> -0.740427 | X36: =LN(V36) -> 11.232485 | Y36: 1.9 | Z36: =(Y36-AVERAGE($Y$2:$Y$261))/STDEV($Y$2:$Y$261) -> -0.54565832 | AA36: =LN(Y36) -> 0.64185389 | AB36: 215471 | AC36: 4970 | AD36: =AC36/I36 -> 0.0048022525 | AE36: =0.5*T36+0.5*U36 -> 0.88680151 | AF36: =AE36*P36 -> -0.053208091 | AG36: =LN(1+AF36) -> -0.054675947 | AH36: =(AF36-AVERAGE($AF$2:$AF$261))/STDEV($AF$2:$AF$261) -> -0.54164276 | AI36: =LN(F36)-LN(F35) -> 0.023274694 | AJ36: =K36-K35 -> -0.029795176 | AK36: =Y36-Y35 -> -0.6 | AL36: =LN(V36)-LN(V35) -> 0.0049875415
A37: BE | B37: 2019 | C37: 0 | D37: 0 | E37: 1 | F37: 1201.33 | G37: =(F37-AVERAGE($F$2:$F$261))/STDEV($F$2:$F$261) -> -0.36812206 | H37: =LN(F37) -> 7.0911846 | I37: 1039426 | J37: 75 | K37: =(J37/I37)*100 -> 0.0072155209 | L37: =(K37-AVERAGE($K$2:$K$261))/STDEV($K$2:$K$261) -> 0.065838322 | M37: 1.0368889 | N37: =(M37-AVERAGE($M$2:$M$261))/STDEV($M$2:$M$261) -> 0.42644191 | O37: 1.43 | P37: -0.07 | Q37: 5263 | R37: =[1]Feuil1!J71/panel_choc_taux_suisse_2014_202!Q37 -> 138735.85 | S37: 42.9 | T37: =(R37-AVERAGE($R$2:$R$261))/STDEV($R$2:$R$261) -> 1.3888532 | U37: =(S37-AVERAGE($S$2:$S$261))/STDEV($S$2:$S$261) -> 0.22025332 | V37: 76225 | W37: =(V37-AVERAGE($V$2:$V$261))/STDEV($V$2:$V$261) -> -0.70184961 | X37: =LN(V37) -> 11.241445 | Y37: 1.8 | Z37: =(Y37-AVERAGE($Y$2:$Y$261))/STDEV($Y$2:$Y$261) -> -0.63179746 | AA37: =LN(Y37) -> 0.58778666 | AB37: 218932 | AC37: 3417 | AD37: =AC37/I37 -> 0.0032873913 | AE37: =0.5*T37+0.5*U37 -> 0.80455327 | AF37: =AE37*P37 -> -0.056318729 | AG37: =LN(1+AF37) -> -0.057966806 | AH37: =(AF37-AVERAGE($AF$2:$AF$261))/STDEV($AF$2:$AF$261) -> -0.57363142 | AI37: =LN(F37)-LN(F36) -> 0.017067739 | AJ37: =K37-K36 -> 0.0017079073 | AK37: =Y37-Y36 -> -0.1 | AL37: =LN(V37)-LN(V36) -> 0.0089602457
A38: BE | B38: 2020 | C38: 0 | D38: 0 | E38: 1 | F38: 1216.5 | G38: =(F38-AVERAGE($F$2:$F$261))/STDEV($F$2:$F$261) -> -0.29122472 | H38: =LN(F38) -> 7.1037332 | I38: 1043081 | J38: 250 | K38: =(J38/I38)*100 -> 0.023967458 | L38: =(K38-AVERAGE($K$2:$K$261))/STDEV($K$2:$K$261) -> 0.11766855 | M38: 1.0413346 | N38: =(M38-AVERAGE($M$2:$M$261))/STDEV($M$2:$M$261) -> 0.61203885 | O38: 1.33 | P38: -0.1 | Q38: 5262 | R38: =[1]Feuil1!J72/panel_choc_taux_suisse_2014_202!Q38 -> 142420.52 | S38: 44.4 | T38: =(R38-AVERAGE($R$2:$R$261))/STDEV($R$2:$R$261) -> 1.4508165 | U38: =(S38-AVERAGE($S$2:$S$261))/STDEV($S$2:$S$261) -> 0.37169689 | V38: 76834.761 | W38: =(V38-AVERAGE($V$2:$V$261))/STDEV($V$2:$V$261) -> -0.66725413 | X38: =LN(V38) -> 11.249412 | Y38: 2.5 | Z38: =(Y38-AVERAGE($Y$2:$Y$261))/STDEV($Y$2:$Y$261) -> -0.028823482 | AA38: =LN(Y38) -> 0.91629073 | AB38: 222418 | AC38: 3613 | AD38: =AC38/I38 -> 0.003463777 | AE38: =0.5*T38+0.5*U38 -> 0.9112567 | AF38: =AE38*P38 -> -0.09112567 | AG38: =LN(1+AF38) -> -0.095548446 | AH38: =(AF38-AVERAGE($AF$2:$AF$261))/STDEV($AF$2:$AF$261) -> -0.93157324 | AI38: =LN(F38)-LN(F37) -> 0.012548607 | AJ38: =K38-K37 -> 0.016751937 | AK38: =Y38-Y37 -> 0.7 | AL38: =LN(V38)-LN(V37) -> 0.0079676652
A39: BE | B39: 2021 | C39: 0 | D39: 0 | E39: 1 | F39: 1232 | G39: =(F39-AVERAGE($F$2:$F$261))/STDEV($F$2:$F$261) -> -0.2126546 | H39: =LN(F39) -> 7.1163941 | I39: 1047422 | J39: 183 | K39: =(J39/I39)*100 -> 0.017471468 | L39: =(K39-AVERAGE($K$2:$K$261))/STDEV($K$2:$K$261) -> 0.09757006 | M39: 1.0457436 | N39: =(M39-AVERAGE($M$2:$M$261))/STDEV($M$2:$M$261) -> 0.79609897 | O39: 1.25 | P39: -0.08 | Q39: 5700 | R39: =[1]Feuil1!J73/panel_choc_taux_suisse_2014_202!Q39 -> 135640.31 | S39: 48.2 | T39: =(R39-AVERAGE($R$2:$R$261))/STDEV($R$2:$R$261) -> 1.3367972 | U39: =(S39-AVERAGE($S$2:$S$261))/STDEV($S$2:$S$261) -> 0.75535394 | V39: 76681.092 | W39: =(V39-AVERAGE($V$2:$V$261))/STDEV($V$2:$V$261) -> -0.67597274 | X39: =LN(V39) -> 11.24741 | Y39: 2.4 | Z39: =(Y39-AVERAGE($Y$2:$Y$261))/STDEV($Y$2:$Y$261) -> -0.11496262 | AA39: =LN(Y39) -> 0.87546874 | AB39: 226516 | AC39: 3532 | AD39: =AC39/I39 -> 0.0033720888 | AE39: =0.5*T39+0.5*U39 -> 1.0460756 | AF39: =AE39*P39 -> -0.083686046 | AG39: =LN(1+AF39) -> -0.087396228 | AH39: =(AF39-AVERAGE($AF$2:$AF$261))/STDEV($AF$2:$AF$261) -> -0.85506687 | AI39: =LN(F39)-LN(F38) -> 0.012660982 | AJ39: =K39-K38 -> -0.0064959899 | AK39: =Y39-Y38 -> -0.1 | AL39: =LN(V39)-LN(V38) -> -0.0020020026
A40: BE | B40: 2022 | C40: 0 | D40: 0 | E40: 1 | F40: 1243.67 | G40: =(F40-AVERAGE($F$2:$F$261))/STDEV($F$2:$F$261) -> -0.15349891 | H40: =LN(F40) -> 7.125822 | I40: 1051437 | J40: -296 | K40: =(J40/I40)*100 -> -0.028151948 | L40: =(K40-AVERAGE($K$2:$K$261))/STDEV($K$2:$K$261) -> -0.043588068 | M40: 0.98600652 | N40: =(M40-AVERAGE($M$2:$M$261))/STDEV($M$2:$M$261) -> -1.6977493 | O40: 1.21 | P40: -0.04 | Q40: 5339 | R40: =[1]Feuil1!J74/panel_choc_taux_suisse_2014_202!Q40 -> 149116.41 | S40: 46.1 | T40: =(R40-AVERAGE($R$2:$R$261))/STDEV($R$2:$R$261) -> 1.5634179 | U40: =(S40-AVERAGE($S$2:$S$261))/STDEV($S$2:$S$261) -> 0.54333294 | V40: 77371.222 | W40: =(V40-AVERAGE($V$2:$V$261))/STDEV($V$2:$V$261) -> -0.63681745 | X40: =LN(V40) -> 11.25637 | Y40: 1.7 | Z40: =(Y40-AVERAGE($Y$2:$Y$261))/STDEV($Y$2:$Y$261) -> -0.71793661 | AA40: =LN(Y40) -> 0.53062825 | AB40: 230151 | AC40: 4361 | AD40: =AC40/I40 -> 0.004147657 | AE40: =0.5*T40+0.5*U40 -> 1.0533754 | AF40: =AE40*P40 -> -0.042135017 | AG40: =LN(1+AF40) -> -0.043048448 | AH40: =(AF40-AVERAGE($AF$2:$AF$261))/STDEV($AF$2:$AF$261) -> -0.42777134 | AI40: =LN(F40)-LN(F39) -> 0.0094278207 | AJ40: =K40-K39 -> -0.045623416 | AK40: =Y40-Y39 -> -0.7 | AL40: =LN(V40)-LN(V39) -> 0.0089597414
...

Sheet Feuil1
A1: canton | B1: year | C1: CLUSTER 0 | D1: CLUSTER 1 | E1: CLUSTER 2
A2: AG | B2: 2014 | C2: 1 | D2: 0 | E2: 0
A3: AG | B3: 2015 | C3: 1 | D3: 0 | E3: 0
A4: AG | B4: 2016 | C4: 1 | D4: 0 | E4: 0
A5: AG | B5: 2017 | C5: 1 | D5: 0 | E5: 0
A6: AG | B6: 2018 | C6: 1 | D6: 0 | E6: 0
A7: AG | B7: 2019 | C7: 1 | D7: 0 | E7: 0
A8: AG | B8: 2020 | C8: 1 | D8: 0 | E8: 0
A9: AG | B9: 2021 | C9: 1 | D9: 0 | E9: 0
A10: AG | B10: 2022 | C10: 1 | D10: 0 | E10: 0
A11: AG | B11: 2023 | C11: 1 | D11: 0 | E11: 0
A12: AI | B12: 2014 | C12: 1 | D12: 0 | E12: 0
A13: AI | B13: 2015 | C13: 1 | D13: 0 | E13: 0
... A261: ZH | B261: 2023 | C261: 0 | D261: 1 | E261: 0
