Workbook

Sheet 2024
A1: Structure de la population résidante permanente par canton, au 31.12.2024 | S1: T 01.02.03.04
B2: Total | C2: Âge | F2: Sexe | H2: Nationalité | J2: État civil 1 | Q2: Typologie des communes 2
C3: 0–19 | D3: 20–64 | E3: 65 ou plus | F3: Homme | G3: Femme | H3: Suisse | I3: Étranger | J3: Célibataire | K3: Marié | L3: Veuf | M3: Divorcé | N3: Non marié | O3: Lié par un | P3: Partenariat | Q3: Urbain | R3: Intermédiaire | S3: Rural
O4: partenariat | P4: dissous
O5: enregistré
A6: Suisse | B6: 9051029 | C6: 1798934 | D6: 5482842 | E6: 1769253 | F6: 4500389 | G6: 4550640 | H6: 6571141 | I6: 2479888 | J6: 4197332 | K6: 3622769 | L6: 402978 | M6: 811757 | N6: 773 | O6: 10458 | P6: 4196 | Q6: 5883510 | R6: 1924047 | S6: 1243472 | W6: 2023 | X6: 2022 | Y6: 2021 | Z6: 2020 | AA6: 2019 | AB6: 2018 | AC6: 2017 | AD6: 2016 | AE6: 2015 | AF6: 2014
A7: Région lémanique | B7: 1757496 | C7: 368440 | D7: 1078775 | E7: 310281 | F7: 863294 | G7: 894202 | H7: 1149233 | I7: 608263 | J7: 860255 | K7: 655947 | L7: 72167 | M7: 165242 | N7: 237 | O7: 2437 | P7: 976 | Q7: 1249366 | R7: 310273 | S7: 197857 | V7: Région lémanique | W7: ='2023'!$E7 -> 303694 | X7: ='2022'!$E7 -> 296988 | Y7: ='2021'!$E7 -> 292537 | Z7: ='2020'!$E7 -> 287437 | AA7: ='2019'!$E7 -> 284965 | AB7: ='2018'!$E7 -> 280807 | AC7: ='2017'!$E7 -> 277063 | AD7: ='2015'!$E7 -> 268885 | AE7: ='2014'!$E7 -> 263681 | AF7: ='2013'!$E7 -> 257415
A8: Vaud | B8: 855106 | C8: 185265 | D8: 525082 | E8: 144759 | F8: 420878 | G8: 434228 | H8: 564524 | I8: 290582 | J8: 426207 | K8: 315803 | L8: 33518 | M8: 77752 | N8: 93 | O8: 1127 | P8: 464 | Q8: 539600 | R8: 191853 | S8: 123653 | V8: Vaud | W8: ='2023'!E8 -> 141976 | X8: ='2022'!$E8 -> 138839 | Y8: ='2021'!$E8 -> 136678 | Z8: ='2020'!$E8 -> 134512 | AA8: ='2019'!$E8 -> 133375 | AB8: ='2018'!$E8 -> 131400 | AC8: ='2017'!$E8 -> 129778 | AD8: ='2015'!$E8 -> 125957 | AE8: ='2014'!$E8 -> 123612 | AF8: ='2013'!$E8 -> 120806
A9: Valais | B9: 371288 | C9: 71270 | D9: 222567 | E9: 77451 | F9: 185484 | G9: 185804 | H9: 275085 | I9: 96203 | J9: 167048 | K9: 149965 | L9: 18713 | M9: 35034 | N9: 42 | O9: 295 | P9: 123 | Q9: 204474 | R9: 102766 | S9: 64048 | V9: Valais | W9: ='2023'!E9 -> 75330 | X9: ='2022'!$E9 -> 73279 | Y9: ='2021'!$E9 -> 71765 | Z9: ='2020'!$E9 -> 70012 | AA9: ='2019'!$E9 -> 68835 | AB9: ='2018'!$E9 -> 67450 | AC9: ='2017'!$E9 -> 65999 | AD9: ='2015'!$E9 -> 62936 | AE9: ='2014'!$E9 -> 61249 | AF9: ='2013'!$E9 -> 59241
A10: Genève | B10: 531102 | C10: 111905 | D10: 331126 | E10: 88071 | F10: 256932 | G10: 274170 | H10: 309624 | I10: 221478 | J10: 267000 | K10: 190179 | L10: 19936 | M10: 52456 | N10: 102 | O10: 1015 | P10: 389 | Q10: 505292 | R10: 15654 | S10: 10156 | V10: Genève | W10: ='2023'!E10 -> 86388 | X10: ='2022'!$E10 -> 84870 | Y10: ='2021'!$E10 -> 84094 | Z10: ='2020'!$E10 -> 82913 | AA10: ='2019'!$E10 -> 82755 | AB10: ='2018'!$E10 -> 81957 | AC10: ='2017'!$E10 -> 81286 | AD10: ='2015'!$E10 -> 79992 | AE10: ='2014'!$E10 -> 78820 | AF10: ='2013'!$E10 -> 77368
A11: Espace Mittelland | B11: 1962040 | C11: 387356 | D11: 1161375 | E11: 413309 | F11: 970545 | G11: 991495 | H11: 1542684 | I11: 419356 | J11: 895988 | K11: 784232 | L11: 95273 | M11: 183695 | N11: 153 | O11: 1794 | P11: 752 | Q11: 999453 | R11: 537270 | S11: 425317 | V11: Espace Mittelland | W11: ='2023'!E11 -> 404452 | X11: ='2022'!$E11 -> 395493 | Y11: ='2021'!$E11 -> 388595 | Z11: ='2020'!$E11 -> 380604 | AA11: ='2019'!$E11 -> 374763 | AB11: ='2018'!$E11 -> 368054 | AC11: ='2017'!$E11 -> 361895 | AD11: ='2015'!$E11 -> 348989 | AE11: ='2014'!$E11 -> 342345 | AF11: ='2013'!$E11 -> 335112
A12: Berne | B12: 1071216 | C12: 204699 | D12: 627106 | E12: 239411 | F12: 526474 | G12: 544742 | H12: 874493 | I12: 196723 | J12: 485195 | K12: 432205 | L12: 53821 | M12: 98360 | N12: 77 | O12: 1040 | P12: 450 | Q12: 570561 | R12: 286390 | S12: 214265 | V12: Berne | W12: ='2023'!E12 -> 234806 | X12: ='2022'!$E12 -> 230151 | Y12: ='2021'!$E12 -> 226516 | Z12: ='2020'!$E12 -> 222418 | AA12: ='2019'!$E12 -> 218932 | AB12: ='2018'!$E12 -> 215471 | AC12: ='2017'!$E12 -> 211983 | AD12: ='2015'!$E12 -> 204977 | AE12: ='2014'!$E12 -> 201208 | AF12: ='2013'!$E12 -> 197134
A13: Fribourg | B13: 346674 | C13: 75180 | D13: 212249 | E13: 59245 | F13: 173605 | G13: 173069 | H13: 258941 | I13: 87733 | J13: 166312 | K13: 135128 | L13: 13951 | M13: 30814 | N13: 39 | O13: 276 | P13: 117 | Q13: 112369 | R13: 121288 | S13: 113017 | V13: Fribourg | W13: ='2023'!E13 -> 57524 | X13: ='2022'!$E13 -> 55618 | Y13: ='2021'!$E13 -> 54164 | Z13: ='2020'!$E13 -> 52615 | AA13: ='2019'!$E13 -> 51509 | AB13: ='2018'!$E13 -> 50139 | AC13: ='2017'!$E13 -> 48891 | AD13: ='2015'!$E13 -> 46154 | AE13: ='2014'!$E13 -> 44779 | AF13: ='2013'!$E13 -> 43493
A14: Soleure | B14: 289792 | C14: 55995 | D14: 172231 | E14: 61566 | F14: 145155 | G14: 144637 | H14: 215619 | I14: 74173 | J14: 125354 | K14: 122825 | L14: 14063 | M14: 27138 | N14: 13 | O14: 279 | P14: 91 | Q14: 174946 | R14: 52848 | S14: 61998 | V14: Soleure | W14: ='2023'!E14 -> 60059 | X14: ='2022'!$E14 -> 58461 | Y14: ='2021'!$E14 -> 57210 | Z14: ='2020'!$E14 -> 55637 | AA14: ='2019'!$E14 -> 54680 | AB14: ='2018'!$E14 -> 53435 | AC14: ='2017'!$E14 -> 52477 | AD14: ='2015'!$E14 -> 50413 | AE14: ='2014'!$E14 -> 49499 | AF14: ='2013'!$E14 -> 48453
A15: Neuchâtel | B15: 179518 | C15: 36316 | D15: 107200 | E15: 36002 | F15: 88219 | G15: 91299 | H15: 130926 | I15: 48592 | J15: 85351 | K15: 64889 | L15: 9067 | M15: 19980 | N15: 13 | O15: 151 | P15: 65 | Q15: 116375 | R15: 55081 | S15: 8062 | V15: Neuchâtel | W15: ='2023'!E15 -> 35383 | X15: ='2022'!$E15 -> 34940 | Y15: ='2021'!$E15 -> 34603 | Z15: ='2020'!$E15 -> 34128 | AA15: ='2019'!$E15 -> 33980 | AB15: ='2018'!$E15 -> 33677 | AC15: ='2017'!$E15 -> 33458 | AD15: ='2015'!$E15 -> 32924 | AE15: ='2014'!$E15 -> 32633 | AF15: ='2013'!$E15 -> 32241
A16: Jura | B16: 74840 | C16: 15166 | D16: 42589 | E16: 17085 | F16: 37092 | G16: 37748 | H16: 62705 | I16: 12135 | J16: 33776 | K16: 29185 | L16: 4371 | M16: 7403 | N16: 11 | O16: 48 | P16: 29 | Q16: 25202 | R16: 21663 | S16: 27975 | V16: Jura | W16: ='2023'!E16 -> 16680 | X16: ='2022'!$E16 -> 16323 | Y16: ='2021'!$E16 -> 16102 | Z16: ='2020'!$E16 -> 15806 | AA16: ='2019'!$E16 -> 15662 | AB16: ='2018'!$E16 -> 15332 | AC16: ='2017'!$E16 -> 15086 | AD16: ='2015'!$E16 -> 14521 | AE16: ='2014'!$E16 -> 14226 | AF16: ='2013'!$E16 -> 13791
A17: Suisse du Nord-Ouest | B17: 1238515 | C17: 243597 | D17: 744542 | E17: 250376 | F17: 617172 | G17: 621343 | H17: 879052 | I17: 359463 | J17: 553087 | K17: 517056 | L17: 56522 | M17: 109823 | N17: 76 | O17: 1405 | P17: 480 | Q17: 871397 | R17: 239090 | S17: 128028 | V17: Suisse du Nord-Ouest | W17: ='2023'!E17 -> 244841 | X17: ='2022'!$E17 -> 239279 | Y17: ='2021'!$E17 -> 234670 | Z17: ='2020'!$E17 -> 230013 | AA17: ='2019'!$E17 -> 225972 | AB17: ='2018'!$E17 -> 221630 | AC17: ='2017'!$E17 -> 217390 | AD17: ='2015'!$E17 -> 209248 | AE17: ='2014'!$E17 -> 205231 | AF17: ='2013'!$E17 -> 200917
A18: Bâle-Ville | B18: 201384 | C18: 35798 | D18: 125991 | E18: 39595 | F18: 98274 | G18: 103110 | H18: 123481 | I18: 77903 | J18: 102595 | K18: 69429 | L18: 9178 | M18: 19562 | N18: 23 | O18: 434 | P18: 156 | Q18: 201384 | R18: 0 | S18: 0 | V18: Bâle-Ville | W18: ='2023'!E18 -> 39294 | X18: ='2022'!$E18 -> 38894 | Y18: ='2021'!$E18 -> 38827 | Z18: ='2020'!$E18 -> 38729 | AA18: ='2019'!$E18 -> 38760 | AB18: ='2018'!$E18 -> 38715 | AC18: ='2017'!$E18 -> 38739 | AD18: ='2015'!$E18 -> 38834 | AE18: ='2014'!$E18 -> 38866 | AF18: ='2013'!$E18 -> 38809
A19: Bâle-Campagne | B19: 301323 | C19: 58341 | D19: 173054 | E19: 69928 | F19: 147872 | G19: 153451 | H19: 224550 | I19: 76773 | J19: 126947 | K19: 130665 | L19: 15915 | M19: 27276 | N19: 15 | O19: 391 | P19: 100 | Q19: 208275 | R19: 63547 | S19: 29501 | V19: Bâle-Campagne | W19: ='2023'!E19 -> 68536 | X19: ='2022'!$E19 -> 67286 | Y19: ='2021'!$E19 -> 66312 | Z19: ='2020'!$E19 -> 65116 | AA19: ='2019'!$E19 -> 64200 | AB19: ='2018'!$E19 -> 63207 | AC19: ='2017'!$E19 -> 62227 | AD19: ='2015'!$E19 -> 60116 | AE19: ='2014'!$E19 -> 59013 | AF19: ='2013'!$E19 -> 57721
... A37: Tessin | B37: 358903 | C37: 62522 | D37: 210307 | E37: 86074 | F37: 175012 | G37: 183891 | H37: 253361 | I37: 105542 | J37: 158197 | K37: 145030 | L37: 21190 | M37: 34017 | N37: 55 | O37: 293 | P37: 113 | Q37: 262775 | R37: 68457 | S37: 27671 | V37: Tessin | W37: ='2023'!E37 -> 84665 | X37: ='2022'!$E37 -> 83490 | Y37: ='2021'!$E37 -> 82355 | Z37: ='2020'!$E37 -> 81011 | AA37: ='2019'!$E37 -> 80718 | AB37: ='2018'!$E37 -> 79895 | AC37: ='2017'!$E37 -> 78899 | AD37: ='2015'!$E37 -> 76731 | AE37: ='2014'!$E37 -> 75549 | AF37: ='2013'!$E37 -> 73690
A38: 1 Rupture de série: à partir de 2014, les "Sans indication” ne sont pas compris | X38: ='2022'!$E38 -> 0
A39: 2 Selon la typologie des communes 2020 de l’OFS
A40: Source: Office fédéral de la statistique, STATPOP
A41: © OFS
A43: Renseignements: Office fédéral de la statistique (OFS), section Démographie et migration, info.dem@bfs.admin.ch, tél. 058 463 67 11

Sheet 2023
A1: Structure de la population résidante permanente par canton, au 31.12.2023 | S1: T 01.02.03.04
B2: Total | C2: Âge | F2: Sexe | H2: Nationalité | J2: État civil 1 | Q2: Typologie des communes 2
C3: 0–19 | D3: 20–64 | E3: 65 ou plus | F3: Homme | G3: Femme | H3: Suisse | I3: Étranger | J3: Célibataire | K3: Marié | L3: Veuf | M3: Divorcé | N3: Non marié | O3: Lié par un | P3: Partenariat | Q3: Urbain | R3: Intermédiaire | S3: Rural
O4: partenariat | P4: dissous
O5: enregistré
A6: Suisse | B6: 8962258 | C6: 1788440 | D6: 5443532 | E6: 1730286 | F6: 4451532 | G6: 4510726 | H6: 6544970 | I6: 2417288 | J6: 4127991 | K6: 3615921 | L6: 403261 | M6: 797858 | N6: 733 | O6: 11722 | P6: 4018 | Q6: 5825068 | R6: 1904191 | S6: 1232999
A7: Région lémanique | B7: 1736124 | C7: 365836 | D7: 1066594 | E7: 303694 | F7: 851611 | G7: 884513 | H7: 1140993 | I7: 595131 | J7: 842801 | K7: 654392 | L7: 72185 | M7: 162605 | N7: 235 | O7: 2750 | P7: 926 | Q7: 1233324 | R7: 306180 | S7: 196620
A8: Vaud | B8: 845870 | C8: 184231 | D8: 519663 | E8: 141976 | F8: 415697 | G8: 430173 | H8: 561410 | I8: 284460 | J8: 418325 | K8: 315182 | L8: 33595 | M8: 76804 | N8: 90 | O8: 1292 | P8: 444 | Q8: 532960 | R8: 189896 | S8: 123014
A9: Valais | B9: 365844 | C9: 70577 | D9: 219937 | E9: 75330 | F9: 182413 | G9: 183431 | H9: 273857 | I9: 91987 | J9: 163137 | K9: 149547 | L9: 18664 | M9: 33968 | N9: 44 | O9: 310 | P9: 114 | Q9: 201600 | R9: 100756 | S9: 63488
A10: Genève | B10: 524410 | C10: 111028 | D10: 326994 | E10: 86388 | F10: 253501 | G10: 270909 | H10: 305726 | I10: 218684 | J10: 261339 | K10: 189663 | L10: 19926 | M10: 51833 | N10: 101 | O10: 1148 | P10: 368 | Q10: 498764 | R10: 15528 | S10: 10118
A11: Espace Mittelland | B11: 1944753 | C11: 385379 | D11: 1154922 | E11: 404452 | F11: 961157 | G11: 983596 | H11: 1538772 | I11: 405981 | J11: 881538 | K11: 784279 | L11: 95409 | M11: 180496 | N11: 145 | O11: 2007 | P11: 737 | Q11: 989824 | R11: 532754 | S11: 422175
A12: Berne | B12: 1063533 | C12: 203904 | D12: 624823 | E12: 234806 | F12: 522248 | G12: 541285 | H12: 873149 | I12: 190384 | J12: 478542 | K12: 432439 | L12: 54030 | M12: 96804 | N12: 71 | O12: 1148 | P12: 442 | Q12: 565403 | R12: 284906 | S12: 213224
A13: Fribourg | B13: 341537 | C13: 74535 | D13: 209478 | E13: 57524 | F13: 170884 | G13: 170653 | H13: 257057 | I13: 84480 | J13: 162486 | K13: 134688 | L13: 13835 | M13: 30021 | N13: 35 | O13: 320 | P13: 119 | Q13: 111017 | R13: 119040 | S13: 111480
A14: Soleure | B14: 286844 | C14: 55335 | D14: 171450 | E14: 60059 | F14: 143570 | G14: 143274 | H14: 215055 | I14: 71789 | J14: 123185 | K14: 122480 | L14: 14062 | M14: 26671 | N14: 15 | O14: 313 | P14: 88 | Q14: 172737 | R14: 52501 | S14: 61606
A15: Neuchâtel | B15: 178291 | C15: 36388 | D15: 106520 | E15: 35383 | F15: 87554 | G15: 90737 | H15: 130853 | I15: 47438 | J15: 83895 | K15: 65266 | L15: 9108 | M15: 19777 | N15: 12 | O15: 166 | P15: 63 | Q15: 115551 | R15: 54760 | S15: 7980
A16: Jura | B16: 74548 | C16: 15217 | D16: 42651 | E16: 16680 | F16: 36901 | G16: 37647 | H16: 62658 | I16: 11890 | J16: 33430 | K16: 29406 | L16: 4374 | M16: 7223 | N16: 12 | O16: 60 | P16: 25 | Q16: 25116 | R16: 21547 | S16: 27885
A17: Suisse du Nord-Ouest | B17: 1225762 | C17: 241847 | D17: 739074 | E17: 244841 | F17: 609883 | G17: 615879 | H17: 875812 | I17: 349950 | J17: 543408 | K17: 515684 | L17: 56490 | M17: 108031 | N17: 74 | O17: 1539 | P17: 467 | Q17: 862991 | R17: 236261 | S17: 126510
... A37: Tessin | B37: 357720 | C37: 62877 | D37: 210178 | E37: 84665 | F37: 174159 | G37: 183561 | H37: 253794 | I37: 103926 | J37: 156417 | K37: 146114 | L37: 21299 | M37: 33388 | N37: 49 | O37: 342 | P37: 100 | Q37: 261794 | R37: 68213 | S37: 27713
A38: 1 Rupture de série: à partir de 2014, les "Sans indication” ne sont pas compris
A39: 2 Données révisées selon la typologie des communes 2020 de l’OFS
A40: Source: Office fédéral de la statistique, STATPOP
A41: © OFS
A43: Renseignements: Office fédéral de la statistique (OFS), section Démographie et migration, info.dem@bfs.admin.ch, tél. 058 463 67 11

Sheet 2022
A1: Structure de la population résidante permanente par canton, au 31.12.2022 | S1: T 01.02.03.04
B2: Total | C2: Âge | F2: Sexe | H2: Nationalité | J2: État civil 1 | Q2: Typologie des communes 2
C3: 0–19 | D3: 20–64 | E3: 65 ou plus | F3: Homme | G3: Femme | H3: Suisse | I3: Étranger | J3: Célibataire | K3: Marié | L3: Veuf | M3: Divorcé | N3: Non marié | O3: Lié par un | P3: Partenariat | Q3: Urbain | R3: Intermédiaire | S3: Rural
O4: partenariat | P4: dissous
O5: enregistré
A6: Suisse | B6: 8815385 | C6: 1755213 | D6: 5368549 | E6: 1691623 | F6: 4379953 | G6: 4435432 | H6: 6519362 | I6: 2296023 | J6: 4024051 | K6: 3589295 | L6: 402798 | M6: 780357 | N6: 647 | O6: 14293 | P6: 3682 | Q6: 5726146 | R6: 1872834 | S6: 1216405
A7: Région lémanique | B7: 1701827 | C7: 358186 | D7: 1046653 | E7: 296988 | F7: 835051 | G7: 866776 | H7: 1130600 | I7: 571227 | J7: 816952 | K7: 649510 | L7: 72194 | M7: 158686 | N7: 228 | O7: 3360 | P7: 849 | Q7: 1209154 | R7: 299203 | S7: 193470
A8: Vaud | B8: 830431 | C8: 180828 | D8: 510764 | E8: 138839 | F8: 408209 | G8: 422222 | H8: 554772 | I8: 275659 | J8: 405980 | K8: 313352 | L8: 33611 | M8: 75333 | N8: 83 | O8: 1646 | P8: 405 | Q8: 523449 | R8: 185819 | S8: 121163
A9: Valais | B9: 357282 | C9: 68941 | D9: 215062 | E9: 73279 | F9: 177835 | G9: 179447 | H9: 272671 | I9: 84611 | J9: 157310 | K9: 148115 | L9: 18653 | M9: 32679 | N9: 38 | O9: 373 | P9: 100 | Q9: 196906 | R9: 98106 | S9: 62270
A10: Genève | B10: 514114 | C10: 108417 | D10: 320827 | E10: 84870 | F10: 249007 | G10: 265107 | H10: 303157 | I10: 210957 | J10: 253662 | K10: 188043 | L10: 19930 | M10: 50674 | N10: 107 | O10: 1341 | P10: 344 | Q10: 488799 | R10: 15278 | S10: 10037
A11: Espace Mittelland | B11: 1918746 | C11: 379054 | D11: 1144199 | E11: 395493 | F11: 948765 | G11: 969981 | H11: 1536189 | I11: 382557 | J11: 862111 | K11: 781413 | L11: 95513 | M11: 176418 | N11: 121 | O11: 2438 | P11: 678 | Q11: 974478 | R11: 526505 | S11: 417763
A12: Berne | B12: 1051437 | C12: 200509 | D12: 620777 | E12: 230151 | F12: 516805 | G12: 534632 | H12: 872661 | I12: 178776 | J12: 469022 | K12: 431354 | L12: 54214 | M12: 94967 | N12: 57 | O12: 1389 | P12: 416 | Q12: 557286 | R12: 282475 | S12: 211676
A13: Fribourg | B13: 334465 | C13: 73118 | D13: 205729 | E13: 55618 | F13: 167569 | G13: 166896 | H13: 255175 | I13: 79290 | J13: 157683 | K13: 133499 | L13: 13755 | M13: 28986 | N13: 28 | O13: 405 | P13: 99 | Q13: 108282 | R13: 116449 | S13: 109734
A14: Soleure | B14: 282408 | C14: 54189 | D14: 169758 | E14: 58461 | F14: 141168 | G14: 141240 | H14: 214403 | I14: 68005 | J14: 120412 | K14: 121474 | L14: 14045 | M14: 25990 | N14: 13 | O14: 367 | P14: 83 | Q14: 169914 | R14: 51743 | S14: 60751
A15: Neuchâtel | B15: 176571 | C15: 36157 | D15: 105474 | E15: 34940 | F15: 86657 | G15: 89914 | H15: 131328 | I15: 45243 | J15: 82116 | K15: 65602 | L15: 9140 | M15: 19433 | N15: 13 | O15: 205 | P15: 61 | Q15: 114199 | R15: 54417 | S15: 7955
A16: Jura | B16: 73865 | C16: 15081 | D16: 42461 | E16: 16323 | F16: 36566 | G16: 37299 | H16: 62622 | I16: 11243 | J16: 32878 | K16: 29484 | L16: 4359 | M16: 7042 | N16: 10 | O16: 72 | P16: 19 | Q16: 24797 | R16: 21421 | S16: 27647
A17: Suisse du Nord-Ouest | B17: 1202435 | C17: 236134 | D17: 727022 | E17: 239279 | F17: 598131 | G17: 604304 | H17: 872250 | I17: 330185 | J17: 528247 | K17: 509976 | L17: 56395 | M17: 105374 | N17: 66 | O17: 1905 | P17: 437 | Q17: 846800 | R17: 231570 | S17: 124065
... A37: Tessin | B37: 354023 | C37: 62193 | D37: 208340 | E37: 83490 | F37: 172337 | G37: 181686 | H37: 254597 | I37: 99426 | J37: 153195 | K37: 146184 | L37: 21357 | M37: 32761 | N37: 43 | O37: 389 | P37: 92 | Q37: 258425 | R37: 67921 | S37: 27677
A38: 1 Rupture de série: à partir de 2014, les "Sans indication” ne sont pas compris
A39: 2 Données révisées selon la typologie des communes 2020 de l’OFS
A40: Source: Office fédéral de la statistique, STATPOP
A41: © OFS
A43: Renseignements: Office fédéral de la statistique (OFS), section Démographie et migration, info.dem@bfs.admin.ch, tél. 058 463 67 11

Sheet 2021
A1: Structure de la population résidante permanente par canton, au 31.12.2021 | S1: T 01.02.03.04
B2: Total | C2: Âge | F2: Sexe | H2: Nationalité | J2: État civil 1 | Q2: Typologie des communes 2
C3: 0–19 | D3: 20–64 | E3: 65 ou plus | F3: Homme | G3: Femme | H3: Suisse | I3: Étranger | J3: Célibataire | K3: Marié | L3: Veuf | M3: Divorcé | N3: Non marié | O3: Lié par un | P3: Partenariat | Q3: Urbain | R3: Intermédiaire | S3: Rural
O4: partenariat | P4: dissous
O5: enregistré
A6: Suisse | B6: 8738791 | C6: 1742898 | D6: 5334574 | E6: 1661319 | F6: 4338203 | G6: 4400588 | H6: 6494610 | I6: 2244181 | J6: 3963699 | K6: 3580260 | L6: 403549 | M6: 767336 | N6: 636 | O6: 19705 | P6: 3343 | Q6: 5675384 | R6: 1857637 | S6: 1205770
A7: Région lémanique | B7: 1685625 | C7: 355581 | D7: 1037507 | E7: 292537 | F7: 826704 | G7: 858921 | H7: 1124459 | I7: 561166 | J7: 802549 | K7: 649059 | L7: 72504 | M7: 156154 | N7: 210 | O7: 4310 | P7: 789 | Q7: 1197579 | R7: 296063 | S7: 191983
A8: Vaud | B8: 822968 | C8: 179789 | D8: 506501 | E8: 136678 | F8: 404311 | G8: 418657 | H8: 550447 | I8: 272521 | J8: 399014 | K8: 313418 | L8: 33901 | M8: 74074 | N8: 77 | O8: 2076 | P8: 386 | Q8: 518404 | R8: 184528 | S8: 120036
A9: Valais | B9: 353209 | C9: 68414 | D9: 213030 | E9: 71765 | F9: 175475 | G9: 177734 | H9: 271208 | I9: 82001 | J9: 154332 | K9: 147735 | L9: 18537 | M9: 31922 | N9: 31 | O9: 554 | P9: 83 | Q9: 194781 | R9: 96527 | S9: 61901
A10: Genève | B10: 509448 | C10: 107378 | D10: 317976 | E10: 84094 | F10: 246918 | G10: 262530 | H10: 302804 | I10: 206644 | J10: 249203 | K10: 187906 | L10: 20066 | M10: 50158 | N10: 102 | O10: 1680 | P10: 320 | Q10: 484394 | R10: 15008 | S10: 10046
A11: Espace Mittelland | B11: 1907491 | C11: 377165 | D11: 1141731 | E11: 388595 | F11: 942630 | G11: 964861 | H11: 1532757 | I11: 374734 | J11: 851601 | K11: 782070 | L11: 96071 | M11: 173602 | N11: 125 | O11: 3347 | P11: 620 | Q11: 970275 | R11: 522789 | S11: 414427
A12: Berne | B12: 1047422 | C12: 199736 | D12: 621170 | E12: 226516 | F12: 514583 | G12: 532839 | H12: 871574 | I12: 175848 | J12: 464546 | K12: 432209 | L12: 54598 | M12: 93638 | N12: 58 | O12: 1965 | P12: 389 | Q12: 555409 | R12: 281596 | S12: 210417
A13: Fribourg | B13: 329860 | C13: 72300 | D13: 203396 | E13: 54164 | F13: 165084 | G13: 164776 | H13: 253070 | I13: 76790 | J13: 154358 | K13: 132899 | L13: 13688 | M13: 28253 | N13: 26 | O13: 546 | P13: 79 | Q13: 107430 | R13: 114335 | S13: 108095
A14: Soleure | B14: 280245 | C14: 53622 | D14: 169413 | E14: 57210 | F14: 140047 | G14: 140198 | H14: 213728 | I14: 66517 | J14: 118971 | K14: 120954 | L14: 14088 | M14: 25620 | N14: 15 | O14: 489 | P14: 84 | Q14: 168651 | R14: 51321 | S14: 60273
A15: Neuchâtel | B15: 176166 | C15: 36347 | D15: 105216 | E15: 34603 | F15: 86394 | G15: 89772 | H15: 131653 | I15: 44513 | J15: 81073 | K15: 66304 | L15: 9297 | M15: 19176 | N15: 14 | O15: 251 | P15: 51 | Q15: 114088 | R15: 54178 | S15: 7900
A16: Jura | B16: 73798 | C16: 15160 | D16: 42536 | E16: 16102 | F16: 36522 | G16: 37276 | H16: 62732 | I16: 11066 | J16: 32653 | K16: 29704 | L16: 4400 | M16: 6915 | N16: 12 | O16: 96 | P16: 17 | Q16: 24697 | R16: 21359 | S16: 27742
A17: Suisse du Nord-Ouest | B17: 1191939 | C17: 233565 | D17: 723704 | E17: 234670 | F17: 592477 | G17: 599462 | H17: 868904 | I17: 323035 | J17: 520749 | K17: 507988 | L17: 56414 | M17: 103628 | N17: 67 | O17: 2667 | P17: 395 | Q17: 840279 | R17: 228998 | S17: 122662
... A37: Tessin | B37: 352181 | C37: 62356 | D37: 207470 | E37: 82355 | F37: 171449 | G37: 180732 | H37: 254310 | I37: 97871 | J37: 151360 | K37: 146769 | L37: 21284 | M37: 32119 | N37: 43 | O37: 520 | P37: 84 | Q37: 256533 | R37: 67955 | S37: 27693
A38: 1 Rupture de série: à partir de 2014, les "Sans indication” ne sont pas compris
A39: 2 Données révisées selon la typologie des communes 2020 de l’OFS
A40: Source: Office fédéral de la statistique, STATPOP
A41: © OFS
A43: Renseignements: Office fédéral de la statistique (OFS), section Démographie et migration, info.dem@bfs.admin.ch, tél. 058 463 67 11

Sheet 2020
A1: Structure de la population résidante permanente par canton, au 31.12.2020 | S1: T 01.02.03.04
B2: Total | C2: Âge | F2: Sexe | H2: Nationalité | J2: État civil 1 | Q2: Typologie des communes 2
C3: 0–19 | D3: 20–64 | E3: 65 ou plus | F3: Homme | G3: Femme | H3: Suisse | I3: Étranger | J3: Célibataire | K3: Marié | L3: Veuf | M3: Divorcé | N3: Non marié | O3: Lié par un | P3: Partenariat | Q3: Urbain | R3: Intermédiaire | S3: Rural
O4: partenariat | P4: dissous
O5: enregistré
A6: Suisse | B6: 8670300 | C6: 1726301 | D6: 5314329 | E6: 1629670 | F6: 4302599 | G6: 4367701 | H6: 6459512 | I6: 2210788 | J6: 3903333 | K6: 3588894 | L6: 403471 | M6: 751735 | N6: 617 | O6: 19022 | P6: 2981 | Q6: 5638803 | R6: 1837110 | S6: 1194387
A7: Région lémanique | B7: 1669608 | C7: 352457 | D7: 1029714 | E7: 287437 | F7: 818492 | G7: 851116 | H7: 1115756 | I7: 553852 | J7: 786918 | K7: 652560 | L7: 72456 | M7: 152562 | N7: 197 | O7: 4166 | P7: 693 | Q7: 1188033 | R7: 291686 | S7: 189889
A8: Vaud | B8: 814762 | C8: 178201 | D8: 502049 | E8: 134512 | F8: 400217 | G8: 414545 | H8: 544045 | I8: 270717 | J8: 390456 | K8: 315488 | L8: 33856 | M8: 72495 | N8: 74 | O8: 2046 | P8: 322 | Q8: 514051 | R8: 182217 | S8: 118494
A9: Valais | B9: 348503 | C9: 67768 | D9: 210723 | E9: 70012 | F9: 172955 | G9: 175548 | H9: 268980 | I9: 79523 | J9: 150781 | K9: 147805 | L9: 18447 | M9: 30828 | N9: 32 | O9: 514 | P9: 80 | Q9: 192513 | R9: 94713 | S9: 61277
A10: Genève | B10: 506343 | C10: 106488 | D10: 316942 | E10: 82913 | F10: 245320 | G10: 261023 | H10: 302731 | I10: 203612 | J10: 245681 | K10: 189267 | L10: 20153 | M10: 49239 | N10: 91 | O10: 1606 | P10: 291 | Q10: 481469 | R10: 14756 | S10: 10118
A11: Espace Mittelland | B11: 1895693 | C11: 374276 | D11: 1140813 | E11: 380604 | F11: 936569 | G11: 959124 | H11: 1526914 | I11: 368779 | J11: 840219 | K11: 785146 | L11: 96427 | M11: 169945 | N11: 118 | O11: 3232 | P11: 550 | Q11: 967153 | R11: 517522 | S11: 411018
A12: Berne | B12: 1043081 | C12: 198128 | D12: 622535 | E12: 222418 | F12: 512275 | G12: 530806 | H12: 869632 | I12: 173449 | J12: 459524 | K12: 434172 | L12: 54887 | M12: 92146 | N12: 55 | O12: 1922 | P12: 355 | Q12: 553983 | R12: 279815 | S12: 209283
A13: Fribourg | B13: 325547 | C13: 71573 | D13: 201359 | E13: 52615 | F13: 163010 | G13: 162537 | H13: 250336 | I13: 75211 | J13: 151169 | K13: 133014 | L13: 13548 | M13: 27198 | N13: 26 | O13: 515 | P13: 64 | Q13: 106927 | R13: 112408 | S13: 106212
A14: Soleure | B14: 277462 | C14: 52851 | D14: 168974 | E14: 55637 | F14: 138626 | G14: 138836 | H14: 212535 | I14: 64927 | J14: 117216 | K14: 120496 | L14: 14082 | M14: 25090 | N14: 14 | O14: 466 | P14: 75 | Q14: 167217 | R14: 50407 | S14: 59838
A15: Neuchâtel | B15: 175894 | C15: 36481 | D15: 105285 | E15: 34128 | F15: 86184 | G15: 89710 | H15: 131671 | I15: 44223 | J15: 79901 | K15: 67413 | L15: 9456 | M15: 18822 | N15: 13 | O15: 246 | P15: 43 | Q15: 114284 | R15: 53731 | S15: 7879
A16: Jura | B16: 73709 | C16: 15243 | D16: 42660 | E16: 15806 | F16: 36474 | G16: 37235 | H16: 62740 | I16: 10969 | J16: 32409 | K16: 30051 | L16: 4454 | M16: 6689 | N16: 10 | O16: 83 | P16: 13 | Q16: 24742 | R16: 21161 | S16: 27806
A17: Suisse du Nord-Ouest | B17: 1181776 | C17: 230414 | D17: 721349 | E17: 230013 | F17: 587202 | G17: 594574 | H17: 863570 | I17: 318206 | J17: 512675 | K17: 508144 | L17: 56434 | M17: 101449 | N17: 65 | O17: 2642 | P17: 340 | Q17: 835245 | R17: 226043 | S17: 120488
... A37: Tessin | B37: 350986 | C37: 62537 | D37: 207438 | E37: 81011 | F37: 170830 | G37: 180156 | H37: 254109 | I37: 96877 | J37: 149783 | K37: 148017 | L37: 21222 | M37: 31365 | N37: 41 | O37: 482 | P37: 74 | Q37: 255363 | R37: 67674 | S37: 27949
A38: 1 Rupture de série: à partir de 2014, les "Sans indication” ne sont pas compris
A39: 2 Données révisées selon la typologie des communes 2020 de l’OFS
A40: Source: Office fédéral de la statistique, STATPOP
A41: © OFS
A43: Renseignements: Office fédéral de la statistique (OFS), section Démographie et migration, info.dem@bfs.admin.ch, tél. 058 463 67 11

Sheet 2019
A1: Structure de la population résidante permanente par canton, au 31.12.2019 | S1: T 01.02.03.04
B2: Total | C2: Âge | F2: Sexe | H2: Nationalité | J2: État civil 1 | Q2: Typologie des communes 2
C3: 0–19 | D3: 20–64 | E3: 65 ou plus | F3: Homme | G3: Femme | H3: Suisse | I3: Étranger | J3: Célibataire | K3: Marié | L3: Veuf | M3: Divorcé | N3: Non marié | O3: Lié par un | P3: Partenariat | Q3: Urbain | R3: Intermédiaire | S3: Rural
O4: partenariat | P4: dissous
O5: enregistré
A6: Suisse | B6: 8606033 | C6: 1717198 | D6: 5283035 | E6: 1605800 | F6: 4268863 | G6: 4337170 | H6: 6430658 | I6: 2175375 | J6: 3843439 | K6: 3599225 | L6: 404591 | M6: 737094 | N6: 596 | O6: 18231 | P6: 2606 | Q6: 5428698 | R6: 1815556 | S6: 1361779
A7: Région lémanique | B7: 1654751 | C7: 350184 | D7: 1019602 | E7: 284965 | F7: 810627 | G7: 844124 | H7: 1109609 | I7: 545142 | J7: 769856 | K7: 657991 | L7: 72804 | M7: 149287 | N7: 179 | O7: 3995 | P7: 588 | Q7: 1147907 | R7: 291320 | S7: 215524
A8: Vaud | B8: 805098 | C8: 176324 | D8: 495399 | E8: 133375 | F8: 395189 | G8: 409909 | H8: 539414 | I8: 265684 | J8: 379802 | K8: 317927 | L8: 34103 | M8: 70898 | N8: 63 | O8: 1998 | P8: 283 | Q8: 496862 | R8: 168764 | S8: 139472
A9: Valais | B9: 345525 | C9: 67783 | D9: 208907 | E9: 68835 | F9: 171254 | G9: 174271 | H9: 267503 | I9: 78022 | J9: 148368 | K9: 148410 | L9: 18435 | M9: 29759 | N9: 32 | O9: 436 | P9: 69 | Q9: 191445 | R9: 88881 | S9: 65199
A10: Genève | B10: 504128 | C10: 106077 | D10: 315296 | E10: 82755 | F10: 244184 | G10: 259944 | H10: 302692 | I10: 201436 | J10: 241686 | K10: 191654 | L10: 20266 | M10: 48630 | N10: 84 | O10: 1561 | P10: 236 | Q10: 459600 | R10: 33675 | S10: 10853
A11: Espace Mittelland | B11: 1886584 | C11: 373779 | D11: 1138042 | E11: 374763 | F11: 931877 | G11: 954707 | H11: 1522281 | I11: 364303 | J11: 830318 | K11: 789245 | L11: 96969 | M11: 166289 | N11: 109 | O11: 3103 | P11: 495 | Q11: 948359 | R11: 481844 | S11: 456381
A12: Berne | B12: 1039426 | C12: 197734 | D12: 622760 | E12: 218932 | F12: 510146 | G12: 529280 | H12: 867141 | I12: 172285 | J12: 455017 | K12: 436634 | L12: 55214 | M12: 90308 | N12: 50 | O12: 1869 | P12: 313 | Q12: 547053 | R12: 269981 | S12: 222392
A13: Fribourg | B13: 321831 | C13: 71387 | D13: 198935 | E13: 51509 | F13: 161177 | G13: 160654 | H13: 248374 | I13: 73457 | J13: 148161 | K13: 133203 | L13: 13550 | M13: 26343 | N13: 21 | O13: 479 | P13: 62 | Q13: 106238 | R13: 99148 | S13: 116445
A14: Soleure | B14: 275247 | C14: 52352 | D14: 168215 | E14: 54680 | F14: 137659 | G14: 137588 | H14: 212104 | I14: 63143 | J14: 115759 | K14: 120186 | L14: 14173 | M14: 24580 | N14: 15 | O14: 443 | P14: 69 | Q14: 166058 | R14: 44948 | S14: 64241
A15: Neuchâtel | B15: 176496 | C15: 36989 | D15: 105527 | E15: 33980 | F15: 86495 | G15: 90001 | H15: 131913 | I15: 44583 | J15: 79300 | K15: 68834 | L15: 9493 | M15: 18588 | N15: 13 | O15: 228 | P15: 40 | Q15: 104213 | R15: 55725 | S15: 16558
A16: Jura | B16: 73584 | C16: 15317 | D16: 42605 | E16: 15662 | F16: 36400 | G16: 37184 | H16: 62749 | I16: 10835 | J16: 32081 | K16: 30388 | L16: 4539 | M16: 6470 | N16: 10 | O16: 84 | P16: 11 | Q16: 24797 | R16: 12042 | S16: 36745
A17: Suisse du Nord-Ouest | B17: 1171157 | C17: 228236 | D17: 716949 | E17: 225972 | F17: 581620 | G17: 589537 | H17: 859050 | I17: 312107 | J17: 504645 | K17: 507452 | L17: 56483 | M17: 99664 | N17: 66 | O17: 2521 | P17: 303 | Q17: 769069 | R17: 252304 | S17: 149784
... A37: Tessin | B37: 351491 | C37: 63125 | D37: 207648 | E37: 80718 | F37: 171141 | G37: 180350 | H37: 254633 | I37: 96858 | J37: 148299 | K37: 150508 | L37: 21273 | M37: 30848 | N37: 41 | O37: 463 | P37: 56 | Q37: 249373 | R37: 64542 | S37: 37576
A38: 1 Rupture de série: à partir de 2014, les "Sans indication” ne sont pas compris
A39: 2 Données révisées selon la typologie des communes 2012 de l’OFS
A40: Source: Office fédéral de la statistique, STATPOP
A41: © OFS
A43: Renseignements: Office fédéral de la statistique (OFS), section Démographie et migration, info.dem@bfs.admin.ch, tél. 058 463 67 11

Sheet 2018
A1: Structure de la population résidante permanente par canton, au 31.12.2018 | S1: T 01.02.03.04
B2: Total | C2: Âge | F2: Sexe | H2: Nationalité | J2: État civil 1 | Q2: Typologie des communes 2
C3: 0–19 | D3: 20–64 | E3: 65 ou plus | F3: Homme | G3: Femme | H3: Suisse | I3: Étranger | J3: Célibataire | K3: Marié | L3: Veuf | M3: Divorcé | N3: Non marié | O3: Lié par un | P3: Partenariat | Q3: Urbain | R3: Intermédiaire | S3: Rural
O4: partenariat | P4: dissous
O5: enregistré
A6: Suisse | B6: 8544527 | C6: 1709458 | D6: 5257768 | E6: 1577301 | F6: 4237121 | G6: 4307406 | H6: 6396252 | I6: 2148275 | J6: 3797529 | K6: 3597800 | L6: 405348 | M6: 723331 | N6: 598 | O6: 17392 | P6: 2305 | Q6: 5389400 | R6: 1801081 | S6: 1354046
A7: Région lémanique | B7: 1642580 | C7: 349186 | D7: 1012587 | E7: 280807 | F7: 804808 | G7: 837772 | H7: 1099297 | I7: 543283 | J7: 758587 | K7: 660079 | L7: 72910 | M7: 146485 | N7: 171 | O7: 3775 | P7: 522 | Q7: 1139661 | R7: 289048 | S7: 213871
A8: Vaud | B8: 799145 | C8: 175670 | D8: 492075 | E8: 131400 | F8: 392529 | G8: 406616 | H8: 533878 | I8: 265267 | J8: 374074 | K8: 319150 | L8: 34214 | M8: 69485 | N8: 60 | O8: 1892 | P8: 247 | Q8: 493915 | R8: 167447 | S8: 137783
A9: Valais | B9: 343955 | C9: 68005 | D9: 208500 | E9: 67450 | F9: 170431 | G9: 173524 | H9: 265879 | I9: 78076 | J9: 147060 | K9: 149070 | L9: 18370 | M9: 28941 | N9: 33 | O9: 408 | P9: 56 | Q9: 190605 | R9: 88191 | S9: 65159
A10: Genève | B10: 499480 | C10: 105511 | D10: 312012 | E10: 81957 | F10: 241848 | G10: 257632 | H10: 299540 | I10: 199940 | J10: 237453 | K10: 191859 | L10: 20326 | M10: 48059 | N10: 78 | O10: 1475 | P10: 219 | Q10: 455141 | R10: 33410 | S10: 10929
A11: Espace Mittelland | B11: 1877154 | C11: 373098 | D11: 1136002 | E11: 368054 | F11: 926783 | G11: 950371 | H11: 1518454 | I11: 358700 | J11: 822245 | K11: 790588 | L11: 97441 | M11: 163311 | N11: 113 | O11: 2955 | P11: 460 | Q11: 944294 | R11: 479038 | S11: 453822
A12: Berne | B12: 1034931 | C12: 197075 | D12: 622385 | E12: 215471 | F12: 507767 | G12: 527164 | H12: 865861 | I12: 169070 | J12: 450898 | K12: 437693 | L12: 55502 | M12: 88677 | N12: 55 | O12: 1787 | P12: 296 | Q12: 544206 | R12: 268531 | S12: 222194
A13: Fribourg | B13: 318760 | C13: 71212 | D13: 197409 | E13: 50139 | F13: 159603 | G13: 159157 | H13: 246400 | I13: 72360 | J13: 146157 | K13: 132851 | L13: 13537 | M13: 25679 | N13: 25 | O13: 444 | P13: 58 | Q13: 105684 | R13: 98241 | S13: 114835
A14: Soleure | B14: 273194 | C14: 52055 | D14: 167704 | E14: 53435 | F14: 136475 | G14: 136719 | H14: 211399 | I14: 61795 | J14: 114497 | K14: 119734 | L14: 14210 | M14: 24262 | N14: 11 | O14: 412 | P14: 61 | Q14: 164793 | R14: 44711 | S14: 63690
A15: Neuchâtel | B15: 176850 | C15: 37361 | D15: 105812 | E15: 33677 | F15: 86621 | G15: 90229 | H15: 132143 | I15: 44707 | J15: 78853 | K15: 69688 | L15: 9652 | M15: 18382 | N15: 12 | O15: 228 | P15: 34 | Q15: 104615 | R15: 55613 | S15: 16622
A16: Jura | B16: 73419 | C16: 15395 | D16: 42692 | E16: 15332 | F16: 36317 | G16: 37102 | H16: 62651 | I16: 10768 | J16: 31840 | K16: 30622 | L16: 4540 | M16: 6311 | N16: 10 | O16: 84 | P16: 11 | Q16: 24996 | R16: 11942 | S16: 36481
A17: Suisse du Nord-Ouest | B17: 1161105 | C17: 226158 | D17: 713317 | E17: 221630 | F17: 576428 | G17: 584677 | H17: 854046 | I17: 307059 | J17: 498190 | K17: 505965 | L17: 56482 | M17: 97709 | N17: 68 | O17: 2408 | P17: 261 | Q17: 762755 | R17: 249587 | S17: 148763
... A37: Tessin | B37: 353343 | C37: 64098 | D37: 209350 | E37: 79895 | F37: 172192 | G37: 181151 | H37: 255116 | I37: 98227 | J37: 148532 | K37: 152586 | L37: 21400 | M37: 30299 | N37: 41 | O37: 431 | P37: 52 | Q37: 250754 | R37: 64692 | S37: 37897
A38: 1 Rupture de série: à partir de 2014, les "Sans indication” ne sont pas compris
A39: 2 Données révisées selon la typologie des communes 2012 de l’OFS
A40: Source: Office fédéral de la statistique, STATPOP
A41: © OFS
A43: Renseignements: Office fédéral de la statistique (OFS), section Démographie et migration, info.dem@bfs.admin.ch, tél. 058 463 67 11

Sheet 2017
A1: Structure de la population résidante permanente par canton, au 31.12.2017 | S1: T 01.02.03.04
B2: Total | C2: Âge | F2: Sexe | H2: Nationalité | J2: État civil 1 | Q2: Typologie des communes 2
C3: 0–19 | D3: 20–64 | E3: 65 ou plus | F3: Homme | G3: Femme | H3: Suisse | I3: Étranger | J3: Célibataire | K3: Marié | L3: Veuf | M3: Divorcé | N3: Non marié | O3: Lié par un | P3: Partenariat | Q3: Urbain | R3: Intermédiaire | S3: Rural
O4: partenariat | P4: dissous
O5: enregistré
A6: Suisse | B6: 8484130 | C6: 1700494 | D6: 5233271 | E6: 1550365 | F6: 4206434 | G6: 4277696 | H6: 6357738 | I6: 2126392 | J6: 3755372 | K6: 3592368 | L6: 406117 | M6: 711025 | N6: 588 | O6: 16435 | P6: 2001 | Q6: 5350159 | R6: 1788866 | S6: 1345105
A7: Région lémanique | B7: 1629841 | C7: 346875 | D7: 1005903 | E7: 277063 | F7: 798780 | G7: 831061 | H7: 1086874 | I7: 542967 | J7: 747544 | K7: 661155 | L7: 73063 | M7: 143847 | N7: 163 | O7: 3558 | P7: 458 | Q7: 1131227 | R7: 286668 | S7: 211946
A8: Vaud | B8: 793129 | C8: 174446 | D8: 488905 | E8: 129778 | F8: 389504 | G8: 403625 | H8: 527117 | I8: 266012 | J8: 368315 | K8: 319792 | L8: 34382 | M8: 68554 | N8: 57 | O8: 1786 | P8: 216 | Q8: 491022 | R8: 166001 | S8: 136106
A9: Valais | B9: 341463 | C9: 67825 | D9: 207639 | E9: 65999 | F9: 169162 | G9: 172301 | H9: 263082 | I9: 78381 | J9: 145510 | K9: 149095 | L9: 18326 | M9: 28051 | N9: 35 | O9: 378 | P9: 52 | Q9: 189140 | R9: 87399 | S9: 64924
A10: Genève | B10: 495249 | C10: 104604 | D10: 309359 | E10: 81286 | F10: 240114 | G10: 255135 | H10: 296675 | I10: 198574 | J10: 233719 | K10: 192268 | L10: 20355 | M10: 47242 | N10: 71 | O10: 1394 | P10: 190 | Q10: 451065 | R10: 33268 | S10: 10916
A11: Espace Mittelland | B11: 1868886 | C11: 372526 | D11: 1134465 | E11: 361895 | F11: 922655 | G11: 946231 | H11: 1514630 | I11: 354256 | J11: 815367 | K11: 791716 | L11: 97906 | M11: 160544 | N11: 123 | O11: 2792 | P11: 386 | Q11: 940488 | R11: 477371 | S11: 451027
A12: Berne | B12: 1031080 | C12: 196456 | D12: 622641 | E12: 211983 | F12: 505887 | G12: 525193 | H12: 864300 | I12: 166780 | J12: 447643 | K12: 437954 | L12: 55947 | M12: 87497 | N12: 57 | O12: 1696 | P12: 258 | Q12: 541555 | R12: 267914 | S12: 221611
A13: Fribourg | B13: 315120 | C13: 70798 | D13: 195431 | E13: 48891 | F13: 157898 | G13: 157222 | H13: 244188 | I13: 70932 | J13: 143957 | K13: 132279 | L13: 13484 | M13: 24911 | N13: 30 | O13: 408 | P13: 43 | Q13: 104675 | R13: 97299 | S13: 113146
A14: Soleure | B14: 271432 | C14: 51786 | D14: 167169 | E14: 52477 | F14: 135497 | G14: 135935 | H14: 210812 | I14: 60620 | J14: 113401 | K14: 119540 | L14: 14256 | M14: 23766 | N14: 13 | O14: 398 | P14: 44 | Q14: 163697 | R14: 44727 | S14: 63008
A15: Neuchâtel | B15: 177964 | C15: 37939 | D15: 106567 | E15: 33458 | F15: 87093 | G15: 90871 | H15: 132811 | I15: 45153 | J15: 78725 | K15: 71046 | L15: 9692 | M15: 18242 | N15: 14 | O15: 212 | P15: 32 | Q15: 105543 | R15: 55664 | S15: 16757
A16: Jura | B16: 73290 | C16: 15547 | D16: 42657 | E16: 15086 | F16: 36280 | G16: 37010 | H16: 62519 | I16: 10771 | J16: 31641 | K16: 30897 | L16: 4527 | M16: 6128 | N16: 9 | O16: 78 | P16: 9 | Q16: 25018 | R16: 11767 | S16: 36505
A17: Suisse du Nord-Ouest | B17: 1151919 | C17: 224171 | D17: 710358 | E17: 217390 | F17: 571672 | G17: 580247 | H17: 850199 | I17: 301720 | J17: 492796 | K17: 504252 | L17: 56491 | M17: 95794 | N17: 64 | O17: 2261 | P17: 242 | Q17: 756699 | R17: 247674 | S17: 147546
... A37: Tessin | B37: 353709 | C37: 64769 | D37: 210041 | E37: 78899 | F37: 172505 | G37: 181204 | H37: 255122 | I37: 98587 | J37: 148100 | K37: 153870 | L37: 21396 | M37: 29849 | N37: 41 | O37: 408 | P37: 43 | Q37: 251069 | R37: 64529 | S37: 38111
A38: 1 Rupture de série: à partir de 2014, les "Sans indication” ne sont pas compris
A39: 2 Données révisées selon la typologie des communes 2012 de l’OFS
A40: Source: Office fédéral de la statistique, STATPOP
A41: © OFS
A43: Renseignements: Office fédéral de la statistique (OFS), section Démographie et migration, info.dem@bfs.admin.ch, tél. 058 463 67 11

Sheet 2016
A1: Structure de la population résidante permanente par canton, au 31.12.2016 | S1: T 01.02.03.04
B2: Total | C2: Âge | F2: Sexe | H2: Nationalité | J2: État civil 1 | Q2: Typologie des communes 2
C3: 0–19 | D3: 20–64 | E3: 65 ou plus | F3: Homme | G3: Femme | H3: Suisse | I3: Étranger | J3: Célibataire | K3: Marié | L3: Veuf | M3: Divorcé | N3: Non marié | O3: Lié par un | P3: Partenariat | Q3: Urbain | R3: Intermédiaire | S3: Rural
O4: partenariat | P4: dissous
O5: enregistré
A6: Suisse | B6: 8419550 | C6: 1691466 | D6: 5205025 | E6: 1523059 | F6: 4173437 | G6: 4246113 | H6: 6318404 | I6: 2101146 | J6: 3710349 | K6: 3585129 | L6: 406983 | M6: 699200 | N6: 597 | O6: 15324 | P6: 1730 | Q6: 5310882 | R6: 1775009 | S6: 1333659
A7: Région lémanique | B7: 1613522 | C7: 343884 | D7: 996126 | E7: 273512 | F7: 790573 | G7: 822949 | H7: 1074042 | I7: 539480 | J7: 734396 | K7: 661014 | L7: 73218 | M7: 140988 | N7: 166 | O7: 3292 | P7: 392 | Q7: 1120232 | R7: 283984 | S7: 209306
A8: Vaud | B8: 784822 | C8: 172689 | D8: 483842 | E8: 128291 | F8: 385389 | G8: 399433 | H8: 520957 | I8: 263865 | J8: 361457 | K8: 319592 | L8: 34549 | M8: 67313 | N8: 59 | O8: 1639 | P8: 183 | Q8: 486030 | R8: 164628 | S8: 134164
A9: Valais | B9: 339176 | C9: 67739 | D9: 206913 | E9: 64524 | F9: 168072 | G9: 171104 | H9: 260444 | I9: 78732 | J9: 144112 | K9: 149235 | L9: 18259 | M9: 27145 | N9: 37 | O9: 325 | P9: 48 | Q9: 188160 | R9: 86470 | S9: 64546
A10: Genève | B10: 489524 | C10: 103456 | D10: 305371 | E10: 80697 | F10: 237112 | G10: 252412 | H10: 292641 | I10: 196883 | J10: 228827 | K10: 192187 | L10: 20410 | M10: 46530 | N10: 70 | O10: 1328 | P10: 161 | Q10: 446042 | R10: 32886 | S10: 10596
A11: Espace Mittelland | B11: 1859557 | C11: 372064 | D11: 1131995 | E11: 355498 | F11: 917893 | G11: 941664 | H11: 1509290 | I11: 350267 | J11: 807879 | K11: 792454 | L11: 98294 | M11: 157791 | N11: 127 | O11: 2621 | P11: 340 | Q11: 936545 | R11: 475073 | S11: 447939
A12: Berne | B12: 1026464 | C12: 195724 | D12: 622312 | E12: 208428 | F12: 503763 | G12: 522701 | H12: 861567 | I12: 164897 | J12: 443808 | K12: 438512 | L12: 56085 | M12: 86135 | N12: 58 | O12: 1610 | P12: 223 | Q12: 538522 | R12: 267239 | S12: 220703
A13: Fribourg | B13: 311963 | C13: 70825 | D13: 193630 | E13: 47508 | F13: 156360 | G13: 155603 | H13: 242134 | I13: 69829 | J13: 141861 | K13: 131950 | L13: 13452 | M13: 24231 | N13: 34 | O13: 385 | P13: 43 | Q13: 104374 | R13: 96302 | S13: 111287
A14: Soleure | B14: 269441 | C14: 51712 | D14: 166200 | E14: 51529 | F14: 134300 | G14: 135141 | H14: 210240 | I14: 59201 | J14: 112377 | K14: 118905 | L14: 14383 | M14: 23344 | N14: 15 | O14: 368 | P14: 40 | Q14: 162403 | R14: 44526 | S14: 62512
A15: Neuchâtel | B15: 178567 | C15: 38110 | D15: 107176 | E15: 33281 | F15: 87312 | G15: 91255 | H15: 132878 | I15: 45689 | J15: 78415 | K15: 71940 | L15: 9830 | M15: 18152 | N15: 13 | O15: 191 | P15: 26 | Q15: 106213 | R15: 55465 | S15: 16889
A16: Jura | B16: 73122 | C16: 15693 | D16: 42677 | E16: 14752 | F16: 36158 | G16: 36964 | H16: 62471 | I16: 10651 | J16: 31418 | K16: 31147 | L16: 4544 | M16: 5929 | N16: 7 | O16: 67 | P16: 8 | Q16: 25033 | R16: 11541 | S16: 36548
A17: Suisse du Nord-Ouest | B17: 1142156 | C17: 222348 | D17: 706708 | E17: 213100 | F17: 566718 | G17: 575438 | H17: 845728 | I17: 296428 | J17: 486949 | K17: 501849 | L17: 56612 | M17: 94334 | N17: 66 | O17: 2118 | P17: 210 | Q17: 750626 | R17: 245478 | S17: 146052
... A37: Tessin | B37: 354375 | C37: 65054 | D37: 211291 | E37: 78030 | F37: 172877 | G37: 181498 | H37: 254828 | I37: 99547 | J37: 147721 | K37: 155287 | L37: 21432 | M37: 29477 | N37: 39 | O37: 375 | P37: 42 | Q37: 251600 | R37: 64409 | S37: 38366
A38: 1 Rupture de série: à partir de 2014, les "Sans indication” ne sont pas compris
A39: 2 Données révisées selon la typologie des communes 2012 de l’OFS
A40: Source: Office fédéral de la statistique, STATPOP
A41: © OFS
A43: Renseignements: Office fédéral de la statistique (OFS), section Démographie et migration, info.dem@bfs.admin.ch, tél. 058 463 67 11

Sheet 2015
A1: Structure de la population résidante permanente par canton, au 31.12.2015 | S1: T 01.02.03.04
B2: Total | C2: Âge | F2: Sexe | H2: Nationalité | J2: État civil 1 | Q2: Typologie des communes 2
C3: 0–19 | D3: 20–64 | E3: 65 ou plus | F3: Homme | G3: Femme | H3: Suisse | I3: Étranger | J3: Célibataire | K3: Marié | L3: Veuf | M3: Divorcé | N3: Non marié | O3: Lié par un | P3: Partenariat | Q3: Urbain | R3: Intermédiaire | S3: Rural
O4: partenariat | P4: dissous
O5: enregistré
A6: Suisse | B6: 8327126 | C6: 1675503 | D6: 5156571 | E6: 1495052 | F6: 4121471 | G6: 4205655 | H6: 6278459 | I6: 2048667 | J6: 3650651 | K6: 3568702 | L6: 407151 | M6: 684114 | N6: 563 | O6: 14306 | P6: 1446 | Q6: 5254529 | R6: 1752513 | S6: 1320084
A7: Région lémanique | B7: 1593839 | C7: 340411 | D7: 984543 | E7: 268885 | F7: 779927 | G7: 813912 | H7: 1059872 | I7: 533967 | J7: 720102 | K7: 659175 | L7: 73197 | M7: 137698 | N7: 146 | O7: 3139 | P7: 331 | Q7: 1107561 | R7: 280036 | S7: 206242
A8: Vaud | B8: 773407 | C8: 170633 | D8: 476817 | E8: 125957 | F8: 379074 | G8: 394333 | H8: 513739 | I8: 259668 | J8: 353300 | K8: 318102 | L8: 34604 | M8: 65634 | N8: 51 | O8: 1533 | P8: 159 | Q8: 479658 | R8: 162165 | S8: 131584
A9: Valais | B9: 335696 | C9: 67347 | D9: 205413 | E9: 62936 | F9: 166426 | G9: 169270 | H9: 258612 | I9: 77084 | J9: 142216 | K9: 148810 | L9: 18126 | M9: 26148 | N9: 33 | O9: 312 | P9: 35 | Q9: 186131 | R9: 85263 | S9: 64302
A10: Genève | B10: 484736 | C10: 102431 | D10: 302313 | E10: 79992 | F10: 234427 | G10: 250309 | H10: 287521 | I10: 197215 | J10: 224586 | K10: 192263 | L10: 20467 | M10: 45916 | N10: 62 | O10: 1294 | P10: 137 | Q10: 441772 | R10: 32608 | S10: 10356
A11: Espace Mittelland | B11: 1842251 | C11: 369495 | D11: 1123767 | E11: 348989 | F11: 907412 | G11: 934839 | H11: 1504471 | I11: 337780 | J11: 795493 | K11: 791151 | L11: 98791 | M11: 153932 | N11: 124 | O11: 2446 | P11: 274 | Q11: 928006 | R11: 470255 | S11: 443990
A12: Berne | B12: 1017434 | C12: 194101 | D12: 618356 | E12: 204977 | F12: 498232 | G12: 519202 | H12: 859970 | I12: 157464 | J12: 437160 | K12: 437832 | L12: 56473 | M12: 84189 | N12: 55 | O12: 1522 | P12: 177 | Q12: 533327 | R12: 264701 | S12: 219406
A13: Fribourg | B13: 307510 | C13: 70224 | D13: 191132 | E13: 46154 | F13: 153755 | G13: 153755 | H13: 240229 | I13: 67281 | J13: 138966 | K13: 131261 | L13: 13399 | M13: 23453 | N13: 33 | O13: 349 | P13: 40 | Q13: 103008 | R13: 95112 | S13: 109390
A14: Soleure | B14: 266418 | C14: 51266 | D14: 164739 | E14: 50413 | F14: 132439 | G14: 133979 | H14: 209355 | I14: 57063 | J14: 110681 | K14: 118113 | L14: 14493 | M14: 22736 | N14: 15 | O14: 346 | P14: 31 | Q14: 160616 | R14: 43916 | S14: 61886
A15: Neuchâtel | B15: 178107 | C15: 38117 | D15: 107066 | E15: 32924 | F15: 87021 | G15: 91086 | H15: 132556 | I15: 45551 | J15: 77637 | K15: 72597 | L15: 9888 | M15: 17781 | N15: 13 | O15: 169 | P15: 20 | Q15: 106133 | R15: 55079 | S15: 16895
A16: Jura | B16: 72782 | C16: 15787 | D16: 42474 | E16: 14521 | F16: 35965 | G16: 36817 | H16: 62361 | I16: 10421 | J16: 31049 | K16: 31348 | L16: 4538 | M16: 5773 | N16: 8 | O16: 60 | P16: 6 | Q16: 24922 | R16: 11447 | S16: 36413
A17: Suisse du Nord-Ouest | B17: 1128723 | C17: 219781 | D17: 699694 | E17: 209248 | F17: 559109 | G17: 569614 | H17: 841131 | I17: 287592 | J17: 478839 | K17: 499021 | L17: 56411 | M17: 92221 | N17: 62 | O17: 1980 | P17: 172 | Q17: 742224 | R17: 242336 | S17: 144163
... A37: Tessin | B37: 351946 | C37: 64923 | D37: 210292 | E37: 76731 | F37: 171466 | G37: 180480 | H37: 254288 | I37: 97658 | J37: 146039 | K37: 155145 | L37: 21417 | M37: 28923 | N37: 38 | O37: 344 | P37: 38 | Q37: 249913 | R37: 63852 | S37: 38181
A38: 1 Rupture de série: à partir de 2014, les "Sans indication” ne sont pas compris
A39: 2 Données révisées selon la typologie des communes 2012 de l’OFS
A40: Source: Office fédéral de la statistique, STATPOP
A41: © OFS
A43: Renseignements: Office fédéral de la statistique (OFS), section Démographie et migration, info.dem@bfs.admin.ch, tél. 058 463 67 11

Sheet 2014
A1: Structure de la population résidante permanente par canton, au 31.12.2014 | S1: T 01.02.03.04
B2: Total | C2: Âge | F2: Sexe | H2: Nationalité | J2: État civil 1 | Q2: Typologie des communes 2
C3: 0–19 | D3: 20–64 | E3: 65 ou plus | F3: Homme | G3: Femme | H3: Suisse | I3: Étranger | J3: Célibataire | K3: Marié | L3: Veuf | M3: Divorcé | N3: Non marié | O3: Lié par un | P3: Partenariat | Q3: Urbain | R3: Intermédiaire | S3: Rural
O4: partenariat | P4: dissous
O5: enregistré
A6: Suisse | B6: 8237666 | C6: 1663752 | D6: 5108349 | E6: 1465565 | F6: 4073880 | G6: 4163786 | H6: 6239207 | I6: 1998459 | J6: 3593986 | K6: 3551926 | L6: 407583 | M6: 669047 | N6: 549 | O6: 13282 | P6: 1132 | Q6: 5198543 | R6: 1731663 | S6: 1307460
A7: Région lémanique | B7: 1570594 | C7: 336857 | D7: 970056 | E7: 263681 | F7: 768192 | G7: 802402 | H7: 1047506 | I7: 523088 | J7: 703912 | K7: 656094 | L7: 73255 | M7: 134004 | N7: 148 | O7: 2875 | P7: 259 | Q7: 1091861 | R7: 275255 | S7: 203478
A8: Vaud | B8: 761446 | C8: 168899 | D8: 468935 | E8: 123612 | F8: 373187 | G8: 388259 | H8: 509124 | I8: 252322 | J8: 344572 | K8: 316709 | L8: 34765 | M8: 63790 | N8: 50 | O8: 1408 | P8: 126 | Q8: 473240 | R8: 158932 | S8: 129274
A9: Valais | B9: 331763 | C9: 67069 | D9: 203445 | E9: 61249 | F9: 164399 | G9: 167364 | H9: 256485 | I9: 75278 | J9: 140038 | K9: 148109 | L9: 18051 | M9: 25211 | N9: 37 | O9: 281 | P9: 22 | Q9: 183734 | R9: 84013 | S9: 64016
A10: Genève | B10: 477385 | C10: 100889 | D10: 297676 | E10: 78820 | F10: 230606 | G10: 246779 | H10: 281897 | I10: 195488 | J10: 219302 | K10: 191276 | L10: 20439 | M10: 45003 | N10: 61 | O10: 1186 | P10: 111 | Q10: 434887 | R10: 32310 | S10: 10188
A11: Espace Mittelland | B11: 1826251 | C11: 368125 | D11: 1115781 | E11: 342345 | F11: 898913 | G11: 927338 | H11: 1499972 | I11: 326279 | J11: 784062 | K11: 790017 | L11: 99053 | M11: 150470 | N11: 117 | O11: 2287 | P11: 212 | Q11: 920221 | R11: 465924 | S11: 440106
A12: Berne | B12: 1009370 | C12: 193014 | D12: 615148 | E12: 201208 | F12: 493983 | G12: 515387 | H12: 857869 | I12: 151501 | J12: 431195 | K12: 437474 | L12: 56694 | M12: 82379 | N12: 56 | O12: 1408 | P12: 143 | Q12: 528836 | R12: 262336 | S12: 218198
A13: Fribourg | B13: 303425 | C13: 69995 | D13: 188651 | E13: 44779 | F13: 151612 | G13: 151813 | H13: 238495 | I13: 64930 | J13: 136652 | K13: 130268 | L13: 13398 | M13: 22707 | N13: 29 | O13: 331 | P13: 32 | Q13: 101720 | R13: 94183 | S13: 107522
A14: Soleure | B14: 263719 | C14: 50998 | D14: 163222 | E14: 49499 | F14: 131036 | G14: 132683 | H14: 208749 | I14: 54970 | J14: 108942 | K14: 117721 | L14: 14420 | M14: 22280 | N14: 17 | O14: 317 | P14: 20 | Q14: 158965 | R14: 43512 | S14: 61242
A15: Neuchâtel | B15: 177327 | C15: 38257 | D15: 106437 | E15: 32633 | F15: 86540 | G15: 90787 | H15: 132575 | I15: 44752 | J15: 76527 | K15: 73138 | L15: 9985 | M15: 17490 | N15: 10 | O15: 166 | P15: 11 | Q15: 106001 | R15: 54506 | S15: 16820
A16: Jura | B16: 72410 | C16: 15861 | D16: 42323 | E16: 14226 | F16: 35742 | G16: 36668 | H16: 62284 | I16: 10126 | J16: 30746 | K16: 31416 | L16: 4556 | M16: 5614 | N16: 5 | O16: 65 | P16: 6 | Q16: 24699 | R16: 11387 | S16: 36324
A17: Suisse du Nord-Ouest | B17: 1117158 | C17: 217881 | D17: 694046 | E17: 205231 | F17: 552700 | G17: 564458 | H17: 836996 | I17: 280162 | J17: 471936 | K17: 496388 | L17: 56562 | M17: 90231 | N17: 63 | O17: 1821 | P17: 132 | Q17: 735317 | R17: 239123 | S17: 142718
... A37: Tessin | B37: 350363 | C37: 64890 | D37: 209924 | E37: 75549 | F37: 170541 | G37: 179822 | H37: 253633 | I37: 96730 | J37: 144627 | K37: 155370 | L37: 21411 | M37: 28566 | N37: 34 | O37: 316 | P37: 37 | Q37: 249101 | R37: 63194 | S37: 38068
A38: 1 Rupture de série: à partir de 2014, les "Sans indication” ne sont pas compris
A39: 2 Données révisées selon la typologie des communes 2012 de l’OFS
A40: Source: Office fédéral de la statistique, STATPOP
A41: © OFS
A43: Renseignements: Office fédéral de la statistique (OFS), section Démographie et migration, info.dem@bfs.admin.ch, tél. 058 463 67 11

Sheet 2013
A1: Structure de la population résidante permanente par canton, au 31.12.2013 | S1: T 01.02.03.04
B2: Total | C2: Âge | F2: Sexe | H2: Nationalité | J2: État civil 1 | Q2: Typologie des communes 1
C3: 0–19 | D3: 20–64 | E3: 65 ou plus | F3: Homme | G3: Femme | H3: Suisse | I3: Étranger | J3: Célibataire | K3: Marié | L3: Veuf | M3: Divorcé | N3: Non marié | O3: Lié par un | P3: Partenariat | Q3: Urbain | R3: Intermédiaire | S3: Rural
O4: partenariat | P4: dissous
O5: enregistré
A6: Suisse | B6: 8139631 | C6: 1653511 | D6: 5053373 | E6: 1432747 | F6: 4022091 | G6: 4117540 | H6: 6202184 | I6: 1937447 | J6: 3537837 | K6: 3527929 | L6: 407667 | M6: 652608 | N6: 528 | O6: 12174 | P6: 888 | Q6: 5136353 | R6: 1709957 | S6: 1293321
A7: Région lémanique | B7: 1545817 | C7: 333823 | D7: 954579 | E7: 257415 | F7: 755704 | G7: 790113 | H7: 1037401 | I7: 508416 | J7: 688681 | K7: 650724 | L7: 73017 | M7: 130406 | N7: 134 | O7: 2658 | P7: 197 | Q7: 1075862 | R7: 270145 | S7: 199810
A8: Vaud | B8: 749373 | C8: 167283 | D8: 461284 | E8: 120806 | F8: 366766 | G8: 382607 | H8: 503493 | I8: 245880 | J8: 336758 | K8: 314154 | L8: 34782 | M8: 62238 | N8: 44 | O8: 1306 | P8: 91 | Q8: 467322 | R8: 155778 | S8: 126273
A9: Valais | B9: 327011 | C9: 66744 | D9: 201026 | E9: 59241 | F9: 161991 | G9: 165020 | H9: 254273 | I9: 72738 | J9: 137702 | K9: 146860 | L9: 17922 | M9: 24212 | N9: 31 | O9: 269 | P9: 15 | Q9: 180888 | R9: 82493 | S9: 63630
A10: Genève | B10: 469433 | C10: 99796 | D10: 292269 | E10: 77368 | F10: 226947 | G10: 242486 | H10: 279635 | I10: 189798 | J10: 214221 | K10: 189710 | L10: 20313 | M10: 43956 | N10: 59 | O10: 1083 | P10: 91 | Q10: 427652 | R10: 31874 | S10: 9907
A11: Espace Mittelland | B11: 1808480 | C11: 367067 | D11: 1106301 | E11: 335112 | F11: 889319 | G11: 919161 | H11: 1494209 | I11: 314271 | J11: 773418 | K11: 786890 | L11: 99451 | M11: 146344 | N11: 115 | O11: 2090 | P11: 172 | Q11: 911345 | R11: 461735 | S11: 435400
A12: Berne | B12: 1001232 | C12: 192599 | D12: 611499 | E12: 197134 | F12: 489489 | G12: 511743 | H12: 855692 | I12: 145540 | J12: 426411 | K12: 436073 | L12: 57005 | M12: 80305 | N12: 55 | O12: 1265 | P12: 118 | Q12: 524056 | R12: 260477 | S12: 216699
A13: Fribourg | B13: 297671 | C13: 69271 | D13: 184907 | E13: 43493 | F13: 148710 | G13: 148961 | H13: 235847 | I13: 61824 | J13: 133454 | K13: 128656 | L13: 13395 | M13: 21808 | N13: 28 | O13: 307 | P13: 23 | Q13: 99568 | R13: 92820 | S13: 105283
A14: Soleure | B14: 261437 | C14: 50993 | D14: 161991 | E14: 48453 | F14: 129750 | G14: 131687 | H14: 208257 | I14: 53180 | J14: 107676 | K14: 117278 | L14: 14447 | M14: 21718 | N14: 17 | O14: 284 | P14: 17 | Q14: 157750 | R14: 43063 | S14: 60624
A15: Neuchâtel | B15: 176402 | C15: 38283 | D15: 105878 | E15: 32241 | F15: 86014 | G15: 90388 | H15: 132428 | I15: 43974 | J15: 75537 | K15: 73480 | L15: 10073 | M15: 17121 | N15: 10 | O15: 173 | P15: 8 | Q15: 105579 | R15: 54062 | S15: 16761
A16: Jura | B16: 71738 | C16: 15921 | D16: 42026 | E16: 13791 | F16: 35356 | G16: 36382 | H16: 61985 | I16: 9753 | J16: 30340 | K16: 31403 | L16: 4531 | M16: 5392 | N16: 5 | O16: 61 | P16: 6 | Q16: 24392 | R16: 11313 | S16: 36033
A17: Suisse du Nord-Ouest | B17: 1104353 | C17: 216199 | D17: 687237 | E17: 200917 | F17: 545842 | G17: 558511 | H17: 833402 | I17: 270951 | J17: 464642 | K17: 493279 | L17: 56435 | M17: 88212 | N17: 65 | O17: 1613 | P17: 107 | Q17: 727909 | R17: 235460 | S17: 140984
... A37: Tessin | B37: 346539 | C37: 64664 | D37: 208185 | E37: 73690 | F37: 168446 | G37: 178093 | H37: 252173 | I37: 94366 | J37: 142516 | K37: 154454 | L37: 21335 | M37: 27890 | N37: 30 | O37: 280 | P37: 34 | Q37: 246254 | R37: 62454 | S37: 37831
A38: 1 Données révisées selon la typologie des communes 2012 de l’OFS
A39: Source: Office fédéral de la statistique, STATPOP
A40: © OFS
A42: Renseignements: Office fédéral de la statistique (OFS), section Démographie et migration, info.dem@bfs.admin.ch, tél. 058 463 67 11

Sheet 2012
A1: Structure de la population résidante permanente par canton, au 31.12.2012 | S1: T 01.02.03.04
B2: Total | C2: Âge | F2: Sexe | H2: Nationalité | J2: État civil 1 | Q2: Typologie des communes 1
C3: 0–19 | D3: 20–64 | E3: 65 ou plus | F3: Homme | G3: Femme | H3: Suisse | I3: Étranger | J3: Célibataire | K3: Marié | L3: Veuf | M3: Divorcé | N3: Non marié | O3: Lié par un | P3: Partenariat | Q3: Urbain | R3: Intermédiaire | S3: Rural
O4: partenariat | P4: dissous
O5: enregistré
A6: Suisse | B6: 8039060 | C6: 1643307 | D6: 4997135 | E6: 1398618 | F6: 3968524 | G6: 4070536 | H6: 6169091 | I6: 1869969 | J6: 3477652 | K6: 3507132 | L6: 407661 | M6: 634401 | N6: 502 | O6: 11057 | P6: 655 | Q6: 5072308 | R6: 1687291 | S6: 1279461
A7: Région lémanique | B7: 1519189 | C7: 329582 | D7: 938902 | E7: 250705 | F7: 741999 | G7: 777190 | H7: 1029640 | I7: 489549 | J7: 671776 | K7: 646068 | L7: 72781 | M7: 125884 | N7: 130 | O7: 2415 | P7: 135 | Q7: 1059075 | R7: 264536 | S7: 195578
A8: Vaud | B8: 734356 | C8: 164537 | D8: 452075 | E8: 117744 | F8: 358983 | G8: 375373 | H8: 498089 | I8: 236267 | J8: 326830 | K8: 311274 | L8: 34752 | M8: 60211 | N8: 41 | O8: 1193 | P8: 55 | Q8: 459415 | R8: 152070 | S8: 122871
A9: Valais | B9: 321732 | C9: 66135 | D9: 198363 | E9: 57234 | F9: 159279 | G9: 162453 | H9: 252134 | I9: 69598 | J9: 134957 | K9: 145504 | L9: 17768 | M9: 23229 | N9: 31 | O9: 230 | P9: 13 | Q9: 177499 | R9: 81133 | S9: 63100
A10: Genève | B10: 463101 | C10: 98910 | D10: 288464 | E10: 75727 | F10: 223737 | G10: 239364 | H10: 279417 | I10: 183684 | J10: 209989 | K10: 189290 | L10: 20261 | M10: 42444 | N10: 58 | O10: 992 | P10: 67 | Q10: 422161 | R10: 31333 | S10: 9607
A11: Espace Mittelland | B11: 1788791 | C11: 366053 | D11: 1095393 | E11: 327345 | F11: 878397 | G11: 910394 | H11: 1488524 | I11: 300267 | J11: 761169 | K11: 784059 | L11: 99799 | M11: 141629 | N11: 103 | O11: 1920 | P11: 112 | Q11: 900524 | R11: 456448 | S11: 431819
A12: Berne | B12: 992567 | C12: 192230 | D12: 607430 | E12: 192907 | F12: 484633 | G12: 507934 | H12: 853553 | I12: 139014 | J12: 420573 | K12: 435354 | L12: 57365 | M12: 78007 | N12: 51 | O12: 1146 | P12: 71 | Q12: 518329 | R12: 258327 | S12: 215911
A13: Fribourg | B13: 291445 | C13: 68390 | D13: 181040 | E13: 42015 | F13: 145351 | G13: 146094 | H13: 233154 | I13: 58291 | J13: 130171 | K13: 126838 | L13: 13276 | M13: 20837 | N13: 21 | O13: 282 | P13: 20 | Q13: 97414 | R13: 90988 | S13: 103043
A14: Soleure | B14: 259283 | C14: 51274 | D14: 160742 | E14: 47267 | F14: 128386 | G14: 130897 | H14: 207443 | I14: 51840 | J14: 106473 | K14: 116955 | L14: 14527 | M14: 21040 | N14: 15 | O14: 263 | P14: 10 | Q14: 156262 | R14: 42674 | S14: 60347
A15: Neuchâtel | B15: 174554 | C15: 38264 | D15: 104534 | E15: 31756 | F15: 85050 | G15: 89504 | H15: 132652 | I15: 41902 | J15: 74078 | K15: 73594 | L15: 10112 | M15: 16579 | N15: 11 | O15: 174 | P15: 6 | Q15: 104602 | R15: 53315 | S15: 16637
A16: Jura | B16: 70942 | C16: 15895 | D16: 41647 | E16: 13400 | F16: 34977 | G16: 35965 | H16: 61722 | I16: 9220 | J16: 29874 | K16: 31318 | L16: 4519 | M16: 5166 | N16: 5 | O16: 55 | P16: 5 | Q16: 23917 | R16: 11144 | S16: 35881
A17: Suisse du Nord-Ouest | B17: 1091302 | C17: 214809 | D17: 680238 | E17: 196255 | F17: 538900 | G17: 552402 | H17: 829508 | I17: 261794 | J17: 457174 | K17: 490288 | L17: 56259 | M17: 86027 | N17: 61 | O17: 1410 | P17: 83 | Q17: 719812 | R17: 232085 | S17: 139405
... A37: Tessin | B37: 341652 | C37: 63968 | D37: 205795 | E37: 71889 | F37: 165873 | G37: 175779 | H37: 250320 | I37: 91332 | J37: 139779 | K37: 153081 | L37: 21316 | M37: 27174 | N37: 30 | O37: 248 | P37: 24 | Q37: 242448 | R37: 61435 | S37: 37769
A38: 1 Données révisées selon la typologie des communes 2012 de l’OFS
A39: Source: Office fédéral de la statistique, STATPOP
A40: © OFS
A42: Renseignements: Office fédéral de la statistique (OFS), section Démographie et migration, info.dem@bfs.admin.ch, tél. 058 463 67 11

Sheet 2011
A1: Structure de la population résidante permanente par canton, au 31.12.2011 | S1: T 01.02.03.04
B2: Total | C2: Âge | F2: Sexe | H2: Nationalité | J2: État civil 1 | Q2: Typologie des communes 1
C3: 0–19 | D3: 20–64 | E3: 65 ou plus | F3: Homme | G3: Femme | H3: Suisse | I3: Étranger | J3: Célibataire | K3: Marié | L3: Veuf | M3: Divorcé | N3: Non marié | O3: Lié par un | P3: Partenariat | Q3: Urbain | R3: Intermédiaire | S3: Rural
O4: partenariat | P4: dissous
O5: enregistré
A6: Suisse | B6: 7954662 | C6: 1642543 | D6: 4946967 | E6: 1365152 | F6: 3922253 | G6: 4032409 | H6: 6138668 | I6: 1815994 | J6: 3432503 | K6: 3485079 | L6: 408797 | M6: 617370 | N6: 484 | O6: 9944 | P6: 485 | Q6: 5019466 | R6: 1667410 | S6: 1267786
A7: Région lémanique | B7: 1503500 | C7: 329867 | D7: 929345 | E7: 244288 | F7: 733280 | G7: 770220 | H7: 1025817 | I7: 477683 | J7: 662759 | K7: 642971 | L7: 72845 | M7: 122495 | N7: 128 | O7: 2214 | P7: 88 | Q7: 1049833 | R7: 260731 | S7: 192936
A8: Vaud | B8: 725944 | C8: 164144 | D8: 446880 | E8: 114920 | F8: 354368 | G8: 371576 | H8: 496720 | I8: 229224 | J8: 321344 | K8: 309657 | L8: 34971 | M8: 58802 | N8: 39 | O8: 1091 | P8: 40 | Q8: 455576 | R8: 149640 | S8: 120728
A9: Valais | B9: 317022 | C9: 66149 | D9: 195608 | E9: 55265 | F9: 156733 | G9: 160289 | H9: 249788 | I9: 67234 | J9: 133155 | K9: 143792 | L9: 17662 | M9: 22173 | N9: 31 | O9: 200 | P9: 9 | Q9: 174318 | R9: 80077 | S9: 62627
A10: Genève | B10: 460534 | C10: 99574 | D10: 286857 | E10: 74103 | F10: 222179 | G10: 238355 | H10: 279309 | I10: 181225 | J10: 208260 | K10: 189522 | L10: 20212 | M10: 41520 | N10: 58 | O10: 923 | P10: 39 | Q10: 419939 | R10: 31014 | S10: 9581
A11: Espace Mittelland | B11: 1770429 | C11: 365815 | D11: 1085006 | E11: 319608 | F11: 868522 | G11: 901907 | H11: 1481181 | I11: 289248 | J11: 750122 | K11: 781191 | L11: 100152 | M11: 137072 | N11: 97 | O11: 1711 | P11: 84 | Q11: 890606 | R11: 451778 | S11: 428045
